WARNING:django.request:Not Found: /
WARNING:django.request:Not Found: /favicon.ico
WARNING:django.request:Not Found: /instabotmv
WARNING:django.request:Not Found: /instabotmv/
WARNING:django.security.csrf:Forbidden (CSRF token missing or incorrect.): /instabotmv/login/
ERROR:django.request:Internal Server Error: /instabotmv/login/
Traceback (most recent call last):
  File "C:\Users\crist\AppData\Local\Programs\Python\Python36\lib\site-packages\django\core\handlers\exception.py", line 34, in inner
    response = get_response(request)
  File "C:\Users\crist\AppData\Local\Programs\Python\Python36\lib\site-packages\django\core\handlers\base.py", line 126, in _get_response
    response = self.process_exception_by_middleware(e, request)
  File "C:\Users\crist\AppData\Local\Programs\Python\Python36\lib\site-packages\django\core\handlers\base.py", line 124, in _get_response
    response = wrapped_callback(request, *callback_args, **callback_kwargs)
  File "C:\Users\crist\AppData\Local\Programs\Python\Python36\lib\site-packages\django\views\generic\base.py", line 68, in view
    return self.dispatch(request, *args, **kwargs)
  File "C:\Users\crist\AppData\Local\Programs\Python\Python36\lib\site-packages\django\views\generic\base.py", line 88, in dispatch
    return handler(request, *args, **kwargs)
  File "C:\Users\crist\Documents\MYV\mvbotdjango\InstabotMV\views.py", line 169, in post
    if user.is_superuser == 1:
AttributeError: 'NoneType' object has no attribute 'is_superuser'
ERROR:django.request:Internal Server Error: /instabotmv/stop-bot/
Traceback (most recent call last):
  File "C:\Users\crist\AppData\Local\Programs\Python\Python36\lib\site-packages\django\core\handlers\exception.py", line 34, in inner
    response = get_response(request)
  File "C:\Users\crist\AppData\Local\Programs\Python\Python36\lib\site-packages\django\core\handlers\base.py", line 126, in _get_response
    response = self.process_exception_by_middleware(e, request)
  File "C:\Users\crist\AppData\Local\Programs\Python\Python36\lib\site-packages\django\core\handlers\base.py", line 124, in _get_response
    response = wrapped_callback(request, *callback_args, **callback_kwargs)
  File "C:\Users\crist\AppData\Local\Programs\Python\Python36\lib\site-packages\django\views\generic\base.py", line 68, in view
    return self.dispatch(request, *args, **kwargs)
  File "C:\Users\crist\AppData\Local\Programs\Python\Python36\lib\site-packages\django\contrib\auth\mixins.py", line 52, in dispatch
    return super().dispatch(request, *args, **kwargs)
  File "C:\Users\crist\AppData\Local\Programs\Python\Python36\lib\site-packages\django\views\generic\base.py", line 88, in dispatch
    return handler(request, *args, **kwargs)
TypeError: post() takes 1 positional argument but 2 were given
ERROR:django.request:Internal Server Error: /instabotmv/stop-bot/
Traceback (most recent call last):
  File "C:\Users\crist\AppData\Local\Programs\Python\Python36\lib\site-packages\django\core\handlers\exception.py", line 34, in inner
    response = get_response(request)
  File "C:\Users\crist\AppData\Local\Programs\Python\Python36\lib\site-packages\django\core\handlers\base.py", line 126, in _get_response
    response = self.process_exception_by_middleware(e, request)
  File "C:\Users\crist\AppData\Local\Programs\Python\Python36\lib\site-packages\django\core\handlers\base.py", line 124, in _get_response
    response = wrapped_callback(request, *callback_args, **callback_kwargs)
  File "C:\Users\crist\AppData\Local\Programs\Python\Python36\lib\site-packages\django\views\generic\base.py", line 68, in view
    return self.dispatch(request, *args, **kwargs)
  File "C:\Users\crist\AppData\Local\Programs\Python\Python36\lib\site-packages\django\contrib\auth\mixins.py", line 52, in dispatch
    return super().dispatch(request, *args, **kwargs)
  File "C:\Users\crist\AppData\Local\Programs\Python\Python36\lib\site-packages\django\views\generic\base.py", line 88, in dispatch
    return handler(request, *args, **kwargs)
TypeError: post() takes 1 positional argument but 2 were given
ERROR:django.request:Internal Server Error: /instabotmv/login/
Traceback (most recent call last):
  File "C:\Users\crist\AppData\Local\Programs\Python\Python36\lib\site-packages\django\core\handlers\exception.py", line 34, in inner
    response = get_response(request)
  File "C:\Users\crist\AppData\Local\Programs\Python\Python36\lib\site-packages\django\core\handlers\base.py", line 126, in _get_response
    response = self.process_exception_by_middleware(e, request)
  File "C:\Users\crist\AppData\Local\Programs\Python\Python36\lib\site-packages\django\core\handlers\base.py", line 124, in _get_response
    response = wrapped_callback(request, *callback_args, **callback_kwargs)
  File "C:\Users\crist\AppData\Local\Programs\Python\Python36\lib\site-packages\django\views\generic\base.py", line 68, in view
    return self.dispatch(request, *args, **kwargs)
  File "C:\Users\crist\AppData\Local\Programs\Python\Python36\lib\site-packages\django\views\generic\base.py", line 88, in dispatch
    return handler(request, *args, **kwargs)
  File "C:\Users\crist\Documents\MYV\mvbotdjango\InstabotMV\views.py", line 169, in post
    if user.is_superuser == 1:
AttributeError: 'NoneType' object has no attribute 'is_superuser'
ERROR:django.request:Internal Server Error: /instabotmv/stop-bot/
Traceback (most recent call last):
  File "C:\Users\crist\AppData\Local\Programs\Python\Python36\lib\site-packages\django\core\handlers\exception.py", line 34, in inner
    response = get_response(request)
  File "C:\Users\crist\AppData\Local\Programs\Python\Python36\lib\site-packages\django\core\handlers\base.py", line 126, in _get_response
    response = self.process_exception_by_middleware(e, request)
  File "C:\Users\crist\AppData\Local\Programs\Python\Python36\lib\site-packages\django\core\handlers\base.py", line 124, in _get_response
    response = wrapped_callback(request, *callback_args, **callback_kwargs)
  File "C:\Users\crist\AppData\Local\Programs\Python\Python36\lib\site-packages\django\views\generic\base.py", line 68, in view
    return self.dispatch(request, *args, **kwargs)
  File "C:\Users\crist\AppData\Local\Programs\Python\Python36\lib\site-packages\django\contrib\auth\mixins.py", line 52, in dispatch
    return super().dispatch(request, *args, **kwargs)
  File "C:\Users\crist\AppData\Local\Programs\Python\Python36\lib\site-packages\django\views\generic\base.py", line 88, in dispatch
    return handler(request, *args, **kwargs)
TypeError: post() takes 1 positional argument but 2 were given
WARNING:django.request:Not Found: /favicon.ico
WARNING:django.request:Not Found: /favicon.ico
WARNING:django.request:Not Found: /inde
WARNING:django.request:Not Found: /favicon.ico
ERROR:django.request:Internal Server Error: /admin/InstabotMV/hashtaglist/
Traceback (most recent call last):
  File "C:\Users\crist\AppData\Local\Programs\Python\Python36\lib\site-packages\django\db\backends\utils.py", line 85, in _execute
    return self.cursor.execute(sql, params)
  File "C:\Users\crist\AppData\Local\Programs\Python\Python36\lib\site-packages\django\db\backends\mysql\base.py", line 71, in execute
    return self.cursor.execute(query, args)
  File "C:\Users\crist\AppData\Local\Programs\Python\Python36\lib\site-packages\pymysql\cursors.py", line 170, in execute
    result = self._query(query)
  File "C:\Users\crist\AppData\Local\Programs\Python\Python36\lib\site-packages\pymysql\cursors.py", line 328, in _query
    conn.query(q)
  File "C:\Users\crist\AppData\Local\Programs\Python\Python36\lib\site-packages\pymysql\connections.py", line 517, in query
    self._affected_rows = self._read_query_result(unbuffered=unbuffered)
  File "C:\Users\crist\AppData\Local\Programs\Python\Python36\lib\site-packages\pymysql\connections.py", line 732, in _read_query_result
    result.read()
  File "C:\Users\crist\AppData\Local\Programs\Python\Python36\lib\site-packages\pymysql\connections.py", line 1075, in read
    first_packet = self.connection._read_packet()
  File "C:\Users\crist\AppData\Local\Programs\Python\Python36\lib\site-packages\pymysql\connections.py", line 684, in _read_packet
    packet.check_error()
  File "C:\Users\crist\AppData\Local\Programs\Python\Python36\lib\site-packages\pymysql\protocol.py", line 220, in check_error
    err.raise_mysql_exception(self._data)
  File "C:\Users\crist\AppData\Local\Programs\Python\Python36\lib\site-packages\pymysql\err.py", line 109, in raise_mysql_exception
    raise errorclass(errno, errval)
pymysql.err.InternalError: (1054, "Unknown column 'InstabotMV_hashtaglist.id' in 'field list'")

The above exception was the direct cause of the following exception:

Traceback (most recent call last):
  File "C:\Users\crist\AppData\Local\Programs\Python\Python36\lib\site-packages\django\core\handlers\exception.py", line 34, in inner
    response = get_response(request)
  File "C:\Users\crist\AppData\Local\Programs\Python\Python36\lib\site-packages\django\core\handlers\base.py", line 126, in _get_response
    response = self.process_exception_by_middleware(e, request)
  File "C:\Users\crist\AppData\Local\Programs\Python\Python36\lib\site-packages\django\core\handlers\base.py", line 124, in _get_response
    response = wrapped_callback(request, *callback_args, **callback_kwargs)
  File "C:\Users\crist\AppData\Local\Programs\Python\Python36\lib\site-packages\django\contrib\admin\options.py", line 604, in wrapper
    return self.admin_site.admin_view(view)(*args, **kwargs)
  File "C:\Users\crist\AppData\Local\Programs\Python\Python36\lib\site-packages\django\utils\decorators.py", line 142, in _wrapped_view
    response = view_func(request, *args, **kwargs)
  File "C:\Users\crist\AppData\Local\Programs\Python\Python36\lib\site-packages\django\views\decorators\cache.py", line 44, in _wrapped_view_func
    response = view_func(request, *args, **kwargs)
  File "C:\Users\crist\AppData\Local\Programs\Python\Python36\lib\site-packages\django\contrib\admin\sites.py", line 223, in inner
    return view(request, *args, **kwargs)
  File "C:\Users\crist\AppData\Local\Programs\Python\Python36\lib\site-packages\django\utils\decorators.py", line 45, in _wrapper
    return bound_method(*args, **kwargs)
  File "C:\Users\crist\AppData\Local\Programs\Python\Python36\lib\site-packages\django\utils\decorators.py", line 142, in _wrapped_view
    response = view_func(request, *args, **kwargs)
  File "C:\Users\crist\AppData\Local\Programs\Python\Python36\lib\site-packages\django\contrib\admin\options.py", line 1792, in changelist_view
    'selection_note': _('0 of %(cnt)s selected') % {'cnt': len(cl.result_list)},
  File "C:\Users\crist\AppData\Local\Programs\Python\Python36\lib\site-packages\django\db\models\query.py", line 250, in __len__
    self._fetch_all()
  File "C:\Users\crist\AppData\Local\Programs\Python\Python36\lib\site-packages\django\db\models\query.py", line 1186, in _fetch_all
    self._result_cache = list(self._iterable_class(self))
  File "C:\Users\crist\AppData\Local\Programs\Python\Python36\lib\site-packages\django\db\models\query.py", line 54, in __iter__
    results = compiler.execute_sql(chunked_fetch=self.chunked_fetch, chunk_size=self.chunk_size)
  File "C:\Users\crist\AppData\Local\Programs\Python\Python36\lib\site-packages\django\db\models\sql\compiler.py", line 1065, in execute_sql
    cursor.execute(sql, params)
  File "C:\Users\crist\AppData\Local\Programs\Python\Python36\lib\site-packages\django\db\backends\utils.py", line 100, in execute
    return super().execute(sql, params)
  File "C:\Users\crist\AppData\Local\Programs\Python\Python36\lib\site-packages\django\db\backends\utils.py", line 68, in execute
    return self._execute_with_wrappers(sql, params, many=False, executor=self._execute)
  File "C:\Users\crist\AppData\Local\Programs\Python\Python36\lib\site-packages\django\db\backends\utils.py", line 77, in _execute_with_wrappers
    return executor(sql, params, many, context)
  File "C:\Users\crist\AppData\Local\Programs\Python\Python36\lib\site-packages\django\db\backends\utils.py", line 85, in _execute
    return self.cursor.execute(sql, params)
  File "C:\Users\crist\AppData\Local\Programs\Python\Python36\lib\site-packages\django\db\utils.py", line 89, in __exit__
    raise dj_exc_value.with_traceback(traceback) from exc_value
  File "C:\Users\crist\AppData\Local\Programs\Python\Python36\lib\site-packages\django\db\backends\utils.py", line 85, in _execute
    return self.cursor.execute(sql, params)
  File "C:\Users\crist\AppData\Local\Programs\Python\Python36\lib\site-packages\django\db\backends\mysql\base.py", line 71, in execute
    return self.cursor.execute(query, args)
  File "C:\Users\crist\AppData\Local\Programs\Python\Python36\lib\site-packages\pymysql\cursors.py", line 170, in execute
    result = self._query(query)
  File "C:\Users\crist\AppData\Local\Programs\Python\Python36\lib\site-packages\pymysql\cursors.py", line 328, in _query
    conn.query(q)
  File "C:\Users\crist\AppData\Local\Programs\Python\Python36\lib\site-packages\pymysql\connections.py", line 517, in query
    self._affected_rows = self._read_query_result(unbuffered=unbuffered)
  File "C:\Users\crist\AppData\Local\Programs\Python\Python36\lib\site-packages\pymysql\connections.py", line 732, in _read_query_result
    result.read()
  File "C:\Users\crist\AppData\Local\Programs\Python\Python36\lib\site-packages\pymysql\connections.py", line 1075, in read
    first_packet = self.connection._read_packet()
  File "C:\Users\crist\AppData\Local\Programs\Python\Python36\lib\site-packages\pymysql\connections.py", line 684, in _read_packet
    packet.check_error()
  File "C:\Users\crist\AppData\Local\Programs\Python\Python36\lib\site-packages\pymysql\protocol.py", line 220, in check_error
    err.raise_mysql_exception(self._data)
  File "C:\Users\crist\AppData\Local\Programs\Python\Python36\lib\site-packages\pymysql\err.py", line 109, in raise_mysql_exception
    raise errorclass(errno, errval)
django.db.utils.InternalError: (1054, "Unknown column 'InstabotMV_hashtaglist.id' in 'field list'")
ERROR:django.request:Internal Server Error: /admin/InstabotMV/hashtaglist/
Traceback (most recent call last):
  File "C:\Users\crist\AppData\Local\Programs\Python\Python36\lib\site-packages\django\db\backends\utils.py", line 85, in _execute
    return self.cursor.execute(sql, params)
  File "C:\Users\crist\AppData\Local\Programs\Python\Python36\lib\site-packages\django\db\backends\mysql\base.py", line 71, in execute
    return self.cursor.execute(query, args)
  File "C:\Users\crist\AppData\Local\Programs\Python\Python36\lib\site-packages\pymysql\cursors.py", line 170, in execute
    result = self._query(query)
  File "C:\Users\crist\AppData\Local\Programs\Python\Python36\lib\site-packages\pymysql\cursors.py", line 328, in _query
    conn.query(q)
  File "C:\Users\crist\AppData\Local\Programs\Python\Python36\lib\site-packages\pymysql\connections.py", line 517, in query
    self._affected_rows = self._read_query_result(unbuffered=unbuffered)
  File "C:\Users\crist\AppData\Local\Programs\Python\Python36\lib\site-packages\pymysql\connections.py", line 732, in _read_query_result
    result.read()
  File "C:\Users\crist\AppData\Local\Programs\Python\Python36\lib\site-packages\pymysql\connections.py", line 1075, in read
    first_packet = self.connection._read_packet()
  File "C:\Users\crist\AppData\Local\Programs\Python\Python36\lib\site-packages\pymysql\connections.py", line 684, in _read_packet
    packet.check_error()
  File "C:\Users\crist\AppData\Local\Programs\Python\Python36\lib\site-packages\pymysql\protocol.py", line 220, in check_error
    err.raise_mysql_exception(self._data)
  File "C:\Users\crist\AppData\Local\Programs\Python\Python36\lib\site-packages\pymysql\err.py", line 109, in raise_mysql_exception
    raise errorclass(errno, errval)
pymysql.err.InternalError: (1054, "Unknown column 'InstabotMV_hashtaglist.id' in 'field list'")

The above exception was the direct cause of the following exception:

Traceback (most recent call last):
  File "C:\Users\crist\AppData\Local\Programs\Python\Python36\lib\site-packages\django\core\handlers\exception.py", line 34, in inner
    response = get_response(request)
  File "C:\Users\crist\AppData\Local\Programs\Python\Python36\lib\site-packages\django\core\handlers\base.py", line 126, in _get_response
    response = self.process_exception_by_middleware(e, request)
  File "C:\Users\crist\AppData\Local\Programs\Python\Python36\lib\site-packages\django\core\handlers\base.py", line 124, in _get_response
    response = wrapped_callback(request, *callback_args, **callback_kwargs)
  File "C:\Users\crist\AppData\Local\Programs\Python\Python36\lib\site-packages\django\contrib\admin\options.py", line 604, in wrapper
    return self.admin_site.admin_view(view)(*args, **kwargs)
  File "C:\Users\crist\AppData\Local\Programs\Python\Python36\lib\site-packages\django\utils\decorators.py", line 142, in _wrapped_view
    response = view_func(request, *args, **kwargs)
  File "C:\Users\crist\AppData\Local\Programs\Python\Python36\lib\site-packages\django\views\decorators\cache.py", line 44, in _wrapped_view_func
    response = view_func(request, *args, **kwargs)
  File "C:\Users\crist\AppData\Local\Programs\Python\Python36\lib\site-packages\django\contrib\admin\sites.py", line 223, in inner
    return view(request, *args, **kwargs)
  File "C:\Users\crist\AppData\Local\Programs\Python\Python36\lib\site-packages\django\utils\decorators.py", line 45, in _wrapper
    return bound_method(*args, **kwargs)
  File "C:\Users\crist\AppData\Local\Programs\Python\Python36\lib\site-packages\django\utils\decorators.py", line 142, in _wrapped_view
    response = view_func(request, *args, **kwargs)
  File "C:\Users\crist\AppData\Local\Programs\Python\Python36\lib\site-packages\django\contrib\admin\options.py", line 1792, in changelist_view
    'selection_note': _('0 of %(cnt)s selected') % {'cnt': len(cl.result_list)},
  File "C:\Users\crist\AppData\Local\Programs\Python\Python36\lib\site-packages\django\db\models\query.py", line 250, in __len__
    self._fetch_all()
  File "C:\Users\crist\AppData\Local\Programs\Python\Python36\lib\site-packages\django\db\models\query.py", line 1186, in _fetch_all
    self._result_cache = list(self._iterable_class(self))
  File "C:\Users\crist\AppData\Local\Programs\Python\Python36\lib\site-packages\django\db\models\query.py", line 54, in __iter__
    results = compiler.execute_sql(chunked_fetch=self.chunked_fetch, chunk_size=self.chunk_size)
  File "C:\Users\crist\AppData\Local\Programs\Python\Python36\lib\site-packages\django\db\models\sql\compiler.py", line 1065, in execute_sql
    cursor.execute(sql, params)
  File "C:\Users\crist\AppData\Local\Programs\Python\Python36\lib\site-packages\django\db\backends\utils.py", line 100, in execute
    return super().execute(sql, params)
  File "C:\Users\crist\AppData\Local\Programs\Python\Python36\lib\site-packages\django\db\backends\utils.py", line 68, in execute
    return self._execute_with_wrappers(sql, params, many=False, executor=self._execute)
  File "C:\Users\crist\AppData\Local\Programs\Python\Python36\lib\site-packages\django\db\backends\utils.py", line 77, in _execute_with_wrappers
    return executor(sql, params, many, context)
  File "C:\Users\crist\AppData\Local\Programs\Python\Python36\lib\site-packages\django\db\backends\utils.py", line 85, in _execute
    return self.cursor.execute(sql, params)
  File "C:\Users\crist\AppData\Local\Programs\Python\Python36\lib\site-packages\django\db\utils.py", line 89, in __exit__
    raise dj_exc_value.with_traceback(traceback) from exc_value
  File "C:\Users\crist\AppData\Local\Programs\Python\Python36\lib\site-packages\django\db\backends\utils.py", line 85, in _execute
    return self.cursor.execute(sql, params)
  File "C:\Users\crist\AppData\Local\Programs\Python\Python36\lib\site-packages\django\db\backends\mysql\base.py", line 71, in execute
    return self.cursor.execute(query, args)
  File "C:\Users\crist\AppData\Local\Programs\Python\Python36\lib\site-packages\pymysql\cursors.py", line 170, in execute
    result = self._query(query)
  File "C:\Users\crist\AppData\Local\Programs\Python\Python36\lib\site-packages\pymysql\cursors.py", line 328, in _query
    conn.query(q)
  File "C:\Users\crist\AppData\Local\Programs\Python\Python36\lib\site-packages\pymysql\connections.py", line 517, in query
    self._affected_rows = self._read_query_result(unbuffered=unbuffered)
  File "C:\Users\crist\AppData\Local\Programs\Python\Python36\lib\site-packages\pymysql\connections.py", line 732, in _read_query_result
    result.read()
  File "C:\Users\crist\AppData\Local\Programs\Python\Python36\lib\site-packages\pymysql\connections.py", line 1075, in read
    first_packet = self.connection._read_packet()
  File "C:\Users\crist\AppData\Local\Programs\Python\Python36\lib\site-packages\pymysql\connections.py", line 684, in _read_packet
    packet.check_error()
  File "C:\Users\crist\AppData\Local\Programs\Python\Python36\lib\site-packages\pymysql\protocol.py", line 220, in check_error
    err.raise_mysql_exception(self._data)
  File "C:\Users\crist\AppData\Local\Programs\Python\Python36\lib\site-packages\pymysql\err.py", line 109, in raise_mysql_exception
    raise errorclass(errno, errval)
django.db.utils.InternalError: (1054, "Unknown column 'InstabotMV_hashtaglist.id' in 'field list'")
ERROR:django.request:Internal Server Error: /instabotmv/dashboard/task/new/follow-like/
Traceback (most recent call last):
  File "C:\Users\crist\AppData\Local\Programs\Python\Python36\lib\site-packages\django\core\handlers\exception.py", line 34, in inner
    response = get_response(request)
  File "C:\Users\crist\AppData\Local\Programs\Python\Python36\lib\site-packages\django\core\handlers\base.py", line 126, in _get_response
    response = self.process_exception_by_middleware(e, request)
  File "C:\Users\crist\AppData\Local\Programs\Python\Python36\lib\site-packages\django\core\handlers\base.py", line 124, in _get_response
    response = wrapped_callback(request, *callback_args, **callback_kwargs)
  File "C:\Users\crist\AppData\Local\Programs\Python\Python36\lib\site-packages\django\views\generic\base.py", line 68, in view
    return self.dispatch(request, *args, **kwargs)
  File "C:\Users\crist\AppData\Local\Programs\Python\Python36\lib\site-packages\django\contrib\auth\mixins.py", line 52, in dispatch
    return super().dispatch(request, *args, **kwargs)
  File "C:\Users\crist\AppData\Local\Programs\Python\Python36\lib\site-packages\django\views\generic\base.py", line 88, in dispatch
    return handler(request, *args, **kwargs)
  File "C:\Users\crist\Documents\MYV\mvbotdjango\InstabotMV\views.py", line 279, in get
    return render(request, 'tasks/followAndLike.html', {})
  File "C:\Users\crist\AppData\Local\Programs\Python\Python36\lib\site-packages\django\shortcuts.py", line 36, in render
    content = loader.render_to_string(template_name, context, request, using=using)
  File "C:\Users\crist\AppData\Local\Programs\Python\Python36\lib\site-packages\django\template\loader.py", line 62, in render_to_string
    return template.render(context, request)
  File "C:\Users\crist\AppData\Local\Programs\Python\Python36\lib\site-packages\django\template\backends\django.py", line 61, in render
    return self.template.render(context)
  File "C:\Users\crist\AppData\Local\Programs\Python\Python36\lib\site-packages\django\template\base.py", line 171, in render
    return self._render(context)
  File "C:\Users\crist\AppData\Local\Programs\Python\Python36\lib\site-packages\django\template\base.py", line 163, in _render
    return self.nodelist.render(context)
  File "C:\Users\crist\AppData\Local\Programs\Python\Python36\lib\site-packages\django\template\base.py", line 937, in render
    bit = node.render_annotated(context)
  File "C:\Users\crist\AppData\Local\Programs\Python\Python36\lib\site-packages\django\template\base.py", line 904, in render_annotated
    return self.render(context)
  File "C:\Users\crist\AppData\Local\Programs\Python\Python36\lib\site-packages\django\template\loader_tags.py", line 150, in render
    return compiled_parent._render(context)
  File "C:\Users\crist\AppData\Local\Programs\Python\Python36\lib\site-packages\django\template\base.py", line 163, in _render
    return self.nodelist.render(context)
  File "C:\Users\crist\AppData\Local\Programs\Python\Python36\lib\site-packages\django\template\base.py", line 937, in render
    bit = node.render_annotated(context)
  File "C:\Users\crist\AppData\Local\Programs\Python\Python36\lib\site-packages\django\template\base.py", line 904, in render_annotated
    return self.render(context)
  File "C:\Users\crist\AppData\Local\Programs\Python\Python36\lib\site-packages\django\template\loader_tags.py", line 150, in render
    return compiled_parent._render(context)
  File "C:\Users\crist\AppData\Local\Programs\Python\Python36\lib\site-packages\django\template\base.py", line 163, in _render
    return self.nodelist.render(context)
  File "C:\Users\crist\AppData\Local\Programs\Python\Python36\lib\site-packages\django\template\base.py", line 937, in render
    bit = node.render_annotated(context)
  File "C:\Users\crist\AppData\Local\Programs\Python\Python36\lib\site-packages\django\template\base.py", line 904, in render_annotated
    return self.render(context)
  File "C:\Users\crist\AppData\Local\Programs\Python\Python36\lib\site-packages\django\template\loader_tags.py", line 62, in render
    result = block.nodelist.render(context)
  File "C:\Users\crist\AppData\Local\Programs\Python\Python36\lib\site-packages\django\template\base.py", line 937, in render
    bit = node.render_annotated(context)
  File "C:\Users\crist\AppData\Local\Programs\Python\Python36\lib\site-packages\django\template\base.py", line 904, in render_annotated
    return self.render(context)
  File "C:\Users\crist\AppData\Local\Programs\Python\Python36\lib\site-packages\django\template\loader_tags.py", line 176, in render
    template = context.template.engine.get_template(template_name)
  File "C:\Users\crist\AppData\Local\Programs\Python\Python36\lib\site-packages\django\template\engine.py", line 144, in get_template
    template, origin = self.find_template(template_name)
  File "C:\Users\crist\AppData\Local\Programs\Python\Python36\lib\site-packages\django\template\engine.py", line 126, in find_template
    template = loader.get_template(name, skip=skip)
  File "C:\Users\crist\AppData\Local\Programs\Python\Python36\lib\site-packages\django\template\loaders\base.py", line 30, in get_template
    contents, origin, origin.template_name, self.engine,
  File "C:\Users\crist\AppData\Local\Programs\Python\Python36\lib\site-packages\django\template\base.py", line 156, in __init__
    self.nodelist = self.compile_nodelist()
  File "C:\Users\crist\AppData\Local\Programs\Python\Python36\lib\site-packages\django\template\base.py", line 194, in compile_nodelist
    return parser.parse()
  File "C:\Users\crist\AppData\Local\Programs\Python\Python36\lib\site-packages\django\template\base.py", line 478, in parse
    raise self.error(token, e)
  File "C:\Users\crist\AppData\Local\Programs\Python\Python36\lib\site-packages\django\template\base.py", line 476, in parse
    compiled_result = compile_func(self, token)
  File "C:\Users\crist\AppData\Local\Programs\Python\Python36\lib\site-packages\django\template\defaulttags.py", line 794, in do_for
    " words: %s" % token.contents)
django.template.exceptions.TemplateSyntaxError: 'for' statements should have at least four words: for
ERROR:django.request:Internal Server Error: /instabotmv/dashboard/task/new/follow-like/
Traceback (most recent call last):
  File "C:\Users\crist\AppData\Local\Programs\Python\Python36\lib\site-packages\django\core\handlers\exception.py", line 34, in inner
    response = get_response(request)
  File "C:\Users\crist\AppData\Local\Programs\Python\Python36\lib\site-packages\django\core\handlers\base.py", line 126, in _get_response
    response = self.process_exception_by_middleware(e, request)
  File "C:\Users\crist\AppData\Local\Programs\Python\Python36\lib\site-packages\django\core\handlers\base.py", line 124, in _get_response
    response = wrapped_callback(request, *callback_args, **callback_kwargs)
  File "C:\Users\crist\AppData\Local\Programs\Python\Python36\lib\site-packages\django\views\generic\base.py", line 68, in view
    return self.dispatch(request, *args, **kwargs)
  File "C:\Users\crist\AppData\Local\Programs\Python\Python36\lib\site-packages\django\contrib\auth\mixins.py", line 52, in dispatch
    return super().dispatch(request, *args, **kwargs)
  File "C:\Users\crist\AppData\Local\Programs\Python\Python36\lib\site-packages\django\views\generic\base.py", line 88, in dispatch
    return handler(request, *args, **kwargs)
  File "C:\Users\crist\Documents\MYV\mvbotdjango\InstabotMV\views.py", line 278, in get
    return render(request, 'tasks/followAndLike.html', {'Hasgtags': Hasgtags})
NameError: name 'Hasgtags' is not defined
ERROR:django.request:Internal Server Error: /instabotmv/tags/
Traceback (most recent call last):
  File "C:\Users\crist\AppData\Local\Programs\Python\Python36\lib\site-packages\django\core\handlers\exception.py", line 34, in inner
    response = get_response(request)
  File "C:\Users\crist\AppData\Local\Programs\Python\Python36\lib\site-packages\django\core\handlers\base.py", line 126, in _get_response
    response = self.process_exception_by_middleware(e, request)
  File "C:\Users\crist\AppData\Local\Programs\Python\Python36\lib\site-packages\django\core\handlers\base.py", line 124, in _get_response
    response = wrapped_callback(request, *callback_args, **callback_kwargs)
  File "C:\Users\crist\Documents\MYV\mvbotdjango\InstabotMV\views.py", line 276, in tags
    tags= List_Tag.objects.get(category=category)
  File "C:\Users\crist\AppData\Local\Programs\Python\Python36\lib\site-packages\django\db\models\manager.py", line 82, in manager_method
    return getattr(self.get_queryset(), name)(*args, **kwargs)
  File "C:\Users\crist\AppData\Local\Programs\Python\Python36\lib\site-packages\django\db\models\query.py", line 390, in get
    clone = self.filter(*args, **kwargs)
  File "C:\Users\crist\AppData\Local\Programs\Python\Python36\lib\site-packages\django\db\models\query.py", line 844, in filter
    return self._filter_or_exclude(False, *args, **kwargs)
  File "C:\Users\crist\AppData\Local\Programs\Python\Python36\lib\site-packages\django\db\models\query.py", line 862, in _filter_or_exclude
    clone.query.add_q(Q(*args, **kwargs))
  File "C:\Users\crist\AppData\Local\Programs\Python\Python36\lib\site-packages\django\db\models\sql\query.py", line 1263, in add_q
    clause, _ = self._add_q(q_object, self.used_aliases)
  File "C:\Users\crist\AppData\Local\Programs\Python\Python36\lib\site-packages\django\db\models\sql\query.py", line 1287, in _add_q
    split_subq=split_subq,
  File "C:\Users\crist\AppData\Local\Programs\Python\Python36\lib\site-packages\django\db\models\sql\query.py", line 1225, in build_filter
    condition = self.build_lookup(lookups, col, value)
  File "C:\Users\crist\AppData\Local\Programs\Python\Python36\lib\site-packages\django\db\models\sql\query.py", line 1096, in build_lookup
    lookup = lookup_class(lhs, rhs)
  File "C:\Users\crist\AppData\Local\Programs\Python\Python36\lib\site-packages\django\db\models\lookups.py", line 20, in __init__
    self.rhs = self.get_prep_lookup()
  File "C:\Users\crist\AppData\Local\Programs\Python\Python36\lib\site-packages\django\db\models\fields\related_lookups.py", line 115, in get_prep_lookup
    self.rhs = target_field.get_prep_value(self.rhs)
  File "C:\Users\crist\AppData\Local\Programs\Python\Python36\lib\site-packages\django\db\models\fields\__init__.py", line 965, in get_prep_value
    return int(value)
ValueError: invalid literal for int() with base 10: 'Select your audience'
ERROR:django.request:Internal Server Error: /instabotmv/tags/
Traceback (most recent call last):
  File "C:\Users\crist\AppData\Local\Programs\Python\Python36\lib\site-packages\django\core\handlers\exception.py", line 34, in inner
    response = get_response(request)
  File "C:\Users\crist\AppData\Local\Programs\Python\Python36\lib\site-packages\django\core\handlers\base.py", line 126, in _get_response
    response = self.process_exception_by_middleware(e, request)
  File "C:\Users\crist\AppData\Local\Programs\Python\Python36\lib\site-packages\django\core\handlers\base.py", line 124, in _get_response
    response = wrapped_callback(request, *callback_args, **callback_kwargs)
  File "C:\Users\crist\Documents\MYV\mvbotdjango\InstabotMV\views.py", line 276, in tags
    tags= List_Tag.objects.get(category=category)
  File "C:\Users\crist\AppData\Local\Programs\Python\Python36\lib\site-packages\django\db\models\manager.py", line 82, in manager_method
    return getattr(self.get_queryset(), name)(*args, **kwargs)
  File "C:\Users\crist\AppData\Local\Programs\Python\Python36\lib\site-packages\django\db\models\query.py", line 403, in get
    (self.model._meta.object_name, num)
InstabotMV.models.List_Tag.MultipleObjectsReturned: get() returned more than one List_Tag -- it returned 2!
ERROR:django.request:Internal Server Error: /instabotmv/tags/
Traceback (most recent call last):
  File "C:\Users\crist\AppData\Local\Programs\Python\Python36\lib\site-packages\django\core\handlers\exception.py", line 34, in inner
    response = get_response(request)
  File "C:\Users\crist\AppData\Local\Programs\Python\Python36\lib\site-packages\django\core\handlers\base.py", line 126, in _get_response
    response = self.process_exception_by_middleware(e, request)
  File "C:\Users\crist\AppData\Local\Programs\Python\Python36\lib\site-packages\django\core\handlers\base.py", line 124, in _get_response
    response = wrapped_callback(request, *callback_args, **callback_kwargs)
  File "C:\Users\crist\Documents\MYV\mvbotdjango\InstabotMV\views.py", line 276, in tags
    tags= List_Tag.objects.get(category=category)
  File "C:\Users\crist\AppData\Local\Programs\Python\Python36\lib\site-packages\django\db\models\manager.py", line 82, in manager_method
    return getattr(self.get_queryset(), name)(*args, **kwargs)
  File "C:\Users\crist\AppData\Local\Programs\Python\Python36\lib\site-packages\django\db\models\query.py", line 403, in get
    (self.model._meta.object_name, num)
InstabotMV.models.List_Tag.MultipleObjectsReturned: get() returned more than one List_Tag -- it returned 2!
ERROR:django.request:Internal Server Error: /instabotmv/tags/
Traceback (most recent call last):
  File "C:\Users\crist\AppData\Local\Programs\Python\Python36\lib\site-packages\django\core\handlers\exception.py", line 34, in inner
    response = get_response(request)
  File "C:\Users\crist\AppData\Local\Programs\Python\Python36\lib\site-packages\django\core\handlers\base.py", line 126, in _get_response
    response = self.process_exception_by_middleware(e, request)
  File "C:\Users\crist\AppData\Local\Programs\Python\Python36\lib\site-packages\django\core\handlers\base.py", line 124, in _get_response
    response = wrapped_callback(request, *callback_args, **callback_kwargs)
  File "C:\Users\crist\Documents\MYV\mvbotdjango\InstabotMV\views.py", line 276, in tags
    tags= List_Tag.objects.get(category=category)
  File "C:\Users\crist\AppData\Local\Programs\Python\Python36\lib\site-packages\django\db\models\manager.py", line 82, in manager_method
    return getattr(self.get_queryset(), name)(*args, **kwargs)
  File "C:\Users\crist\AppData\Local\Programs\Python\Python36\lib\site-packages\django\db\models\query.py", line 403, in get
    (self.model._meta.object_name, num)
InstabotMV.models.List_Tag.MultipleObjectsReturned: get() returned more than one List_Tag -- it returned 2!
ERROR:django.request:Internal Server Error: /instabotmv/tags/
Traceback (most recent call last):
  File "C:\Users\crist\AppData\Local\Programs\Python\Python36\lib\site-packages\django\core\handlers\exception.py", line 34, in inner
    response = get_response(request)
  File "C:\Users\crist\AppData\Local\Programs\Python\Python36\lib\site-packages\django\core\handlers\base.py", line 126, in _get_response
    response = self.process_exception_by_middleware(e, request)
  File "C:\Users\crist\AppData\Local\Programs\Python\Python36\lib\site-packages\django\core\handlers\base.py", line 124, in _get_response
    response = wrapped_callback(request, *callback_args, **callback_kwargs)
  File "C:\Users\crist\Documents\MYV\mvbotdjango\InstabotMV\views.py", line 277, in tags
    tags=[tags_serializer(tags) for tag in tags]#Lista de diccionarios
TypeError: 'List_Tag' object is not iterable
ERROR:django.request:Internal Server Error: /instabotmv/tags/
Traceback (most recent call last):
  File "C:\Users\crist\AppData\Local\Programs\Python\Python36\lib\site-packages\django\core\handlers\exception.py", line 34, in inner
    response = get_response(request)
  File "C:\Users\crist\AppData\Local\Programs\Python\Python36\lib\site-packages\django\core\handlers\base.py", line 126, in _get_response
    response = self.process_exception_by_middleware(e, request)
  File "C:\Users\crist\AppData\Local\Programs\Python\Python36\lib\site-packages\django\core\handlers\base.py", line 124, in _get_response
    response = wrapped_callback(request, *callback_args, **callback_kwargs)
  File "C:\Users\crist\Documents\MYV\mvbotdjango\InstabotMV\views.py", line 276, in tags
    tags= List_Tag.objects.get(category=category)
  File "C:\Users\crist\AppData\Local\Programs\Python\Python36\lib\site-packages\django\db\models\manager.py", line 82, in manager_method
    return getattr(self.get_queryset(), name)(*args, **kwargs)
  File "C:\Users\crist\AppData\Local\Programs\Python\Python36\lib\site-packages\django\db\models\query.py", line 403, in get
    (self.model._meta.object_name, num)
InstabotMV.models.List_Tag.MultipleObjectsReturned: get() returned more than one List_Tag -- it returned 2!
ERROR:django.request:Internal Server Error: /instabotmv/tags/
Traceback (most recent call last):
  File "C:\Users\crist\AppData\Local\Programs\Python\Python36\lib\site-packages\django\core\handlers\exception.py", line 34, in inner
    response = get_response(request)
  File "C:\Users\crist\AppData\Local\Programs\Python\Python36\lib\site-packages\django\core\handlers\base.py", line 126, in _get_response
    response = self.process_exception_by_middleware(e, request)
  File "C:\Users\crist\AppData\Local\Programs\Python\Python36\lib\site-packages\django\core\handlers\base.py", line 124, in _get_response
    response = wrapped_callback(request, *callback_args, **callback_kwargs)
  File "C:\Users\crist\Documents\MYV\mvbotdjango\InstabotMV\views.py", line 277, in tags
    tags=[tags_serializer(tags) for tag in tags]#Lista de diccionarios
  File "C:\Users\crist\Documents\MYV\mvbotdjango\InstabotMV\views.py", line 277, in <listcomp>
    tags=[tags_serializer(tags) for tag in tags]#Lista de diccionarios
  File "C:\Users\crist\Documents\MYV\mvbotdjango\InstabotMV\views.py", line 281, in tags_serializer
    return {'name':tags.insta_tag,'category':tags.category}
AttributeError: 'QuerySet' object has no attribute 'insta_tag'
ERROR:django.request:Internal Server Error: /instabotmv/tags/
Traceback (most recent call last):
  File "C:\Users\crist\AppData\Local\Programs\Python\Python36\lib\site-packages\django\core\handlers\exception.py", line 34, in inner
    response = get_response(request)
  File "C:\Users\crist\AppData\Local\Programs\Python\Python36\lib\site-packages\django\core\handlers\base.py", line 126, in _get_response
    response = self.process_exception_by_middleware(e, request)
  File "C:\Users\crist\AppData\Local\Programs\Python\Python36\lib\site-packages\django\core\handlers\base.py", line 124, in _get_response
    response = wrapped_callback(request, *callback_args, **callback_kwargs)
  File "C:\Users\crist\Documents\MYV\mvbotdjango\InstabotMV\views.py", line 277, in tags
    tags=[tags_serializer(tags) for tag in tags]#Lista de diccionarios
  File "C:\Users\crist\Documents\MYV\mvbotdjango\InstabotMV\views.py", line 277, in <listcomp>
    tags=[tags_serializer(tags) for tag in tags]#Lista de diccionarios
  File "C:\Users\crist\Documents\MYV\mvbotdjango\InstabotMV\views.py", line 281, in tags_serializer
    return {'id':tags.id,'name':tags.insta_tag,'category':tags.category}
AttributeError: 'QuerySet' object has no attribute 'id'
ERROR:django.request:Internal Server Error: /instabotmv/tags/
Traceback (most recent call last):
  File "C:\Users\crist\AppData\Local\Programs\Python\Python36\lib\site-packages\django\core\handlers\exception.py", line 34, in inner
    response = get_response(request)
  File "C:\Users\crist\AppData\Local\Programs\Python\Python36\lib\site-packages\django\core\handlers\base.py", line 126, in _get_response
    response = self.process_exception_by_middleware(e, request)
  File "C:\Users\crist\AppData\Local\Programs\Python\Python36\lib\site-packages\django\core\handlers\base.py", line 124, in _get_response
    response = wrapped_callback(request, *callback_args, **callback_kwargs)
  File "C:\Users\crist\Documents\MYV\mvbotdjango\InstabotMV\views.py", line 278, in tags
    return HttpResponse(json.dumps(tags),content_type='application/json')
  File "C:\Users\crist\AppData\Local\Programs\Python\Python36\lib\json\__init__.py", line 231, in dumps
    return _default_encoder.encode(obj)
  File "C:\Users\crist\AppData\Local\Programs\Python\Python36\lib\json\encoder.py", line 199, in encode
    chunks = self.iterencode(o, _one_shot=True)
  File "C:\Users\crist\AppData\Local\Programs\Python\Python36\lib\json\encoder.py", line 257, in iterencode
    return _iterencode(o, 0)
  File "C:\Users\crist\AppData\Local\Programs\Python\Python36\lib\json\encoder.py", line 180, in default
    o.__class__.__name__)
TypeError: Object of type 'HashtagList' is not JSON serializable
ERROR:django.request:Internal Server Error: /instabotmv/tags/
Traceback (most recent call last):
  File "C:\Users\crist\AppData\Local\Programs\Python\Python36\lib\site-packages\django\core\handlers\exception.py", line 34, in inner
    response = get_response(request)
  File "C:\Users\crist\AppData\Local\Programs\Python\Python36\lib\site-packages\django\core\handlers\base.py", line 126, in _get_response
    response = self.process_exception_by_middleware(e, request)
  File "C:\Users\crist\AppData\Local\Programs\Python\Python36\lib\site-packages\django\core\handlers\base.py", line 124, in _get_response
    response = wrapped_callback(request, *callback_args, **callback_kwargs)
  File "C:\Users\crist\Documents\MYV\mvbotdjango\InstabotMV\views.py", line 278, in tags
    return HttpResponse(json.dumps(tags),content_type='application/json')
  File "C:\Users\crist\AppData\Local\Programs\Python\Python36\lib\json\__init__.py", line 231, in dumps
    return _default_encoder.encode(obj)
  File "C:\Users\crist\AppData\Local\Programs\Python\Python36\lib\json\encoder.py", line 199, in encode
    chunks = self.iterencode(o, _one_shot=True)
  File "C:\Users\crist\AppData\Local\Programs\Python\Python36\lib\json\encoder.py", line 257, in iterencode
    return _iterencode(o, 0)
  File "C:\Users\crist\AppData\Local\Programs\Python\Python36\lib\json\encoder.py", line 180, in default
    o.__class__.__name__)
TypeError: Object of type 'HashtagList' is not JSON serializable
ERROR:django.request:Internal Server Error: /instabotmv/dashboard/task/new/follow-like/
Traceback (most recent call last):
  File "C:\Users\crist\AppData\Local\Programs\Python\Python36\lib\site-packages\django\template\base.py", line 470, in parse
    compile_func = self.tags[command]
KeyError: 'static'

During handling of the above exception, another exception occurred:

Traceback (most recent call last):
  File "C:\Users\crist\AppData\Local\Programs\Python\Python36\lib\site-packages\django\core\handlers\exception.py", line 34, in inner
    response = get_response(request)
  File "C:\Users\crist\AppData\Local\Programs\Python\Python36\lib\site-packages\django\core\handlers\base.py", line 126, in _get_response
    response = self.process_exception_by_middleware(e, request)
  File "C:\Users\crist\AppData\Local\Programs\Python\Python36\lib\site-packages\django\core\handlers\base.py", line 124, in _get_response
    response = wrapped_callback(request, *callback_args, **callback_kwargs)
  File "C:\Users\crist\AppData\Local\Programs\Python\Python36\lib\site-packages\django\views\generic\base.py", line 68, in view
    return self.dispatch(request, *args, **kwargs)
  File "C:\Users\crist\AppData\Local\Programs\Python\Python36\lib\site-packages\django\contrib\auth\mixins.py", line 52, in dispatch
    return super().dispatch(request, *args, **kwargs)
  File "C:\Users\crist\AppData\Local\Programs\Python\Python36\lib\site-packages\django\views\generic\base.py", line 88, in dispatch
    return handler(request, *args, **kwargs)
  File "C:\Users\crist\Documents\MYV\mvbotdjango\InstabotMV\views.py", line 296, in get
    return render(request, 'tasks/followAndLike.html', {'Hasgtags': Hasgtags})
  File "C:\Users\crist\AppData\Local\Programs\Python\Python36\lib\site-packages\django\shortcuts.py", line 36, in render
    content = loader.render_to_string(template_name, context, request, using=using)
  File "C:\Users\crist\AppData\Local\Programs\Python\Python36\lib\site-packages\django\template\loader.py", line 61, in render_to_string
    template = get_template(template_name, using=using)
  File "C:\Users\crist\AppData\Local\Programs\Python\Python36\lib\site-packages\django\template\loader.py", line 15, in get_template
    return engine.get_template(template_name)
  File "C:\Users\crist\AppData\Local\Programs\Python\Python36\lib\site-packages\django\template\backends\django.py", line 34, in get_template
    return Template(self.engine.get_template(template_name), self)
  File "C:\Users\crist\AppData\Local\Programs\Python\Python36\lib\site-packages\django\template\engine.py", line 144, in get_template
    template, origin = self.find_template(template_name)
  File "C:\Users\crist\AppData\Local\Programs\Python\Python36\lib\site-packages\django\template\engine.py", line 126, in find_template
    template = loader.get_template(name, skip=skip)
  File "C:\Users\crist\AppData\Local\Programs\Python\Python36\lib\site-packages\django\template\loaders\base.py", line 30, in get_template
    contents, origin, origin.template_name, self.engine,
  File "C:\Users\crist\AppData\Local\Programs\Python\Python36\lib\site-packages\django\template\base.py", line 156, in __init__
    self.nodelist = self.compile_nodelist()
  File "C:\Users\crist\AppData\Local\Programs\Python\Python36\lib\site-packages\django\template\base.py", line 194, in compile_nodelist
    return parser.parse()
  File "C:\Users\crist\AppData\Local\Programs\Python\Python36\lib\site-packages\django\template\base.py", line 478, in parse
    raise self.error(token, e)
  File "C:\Users\crist\AppData\Local\Programs\Python\Python36\lib\site-packages\django\template\base.py", line 476, in parse
    compiled_result = compile_func(self, token)
  File "C:\Users\crist\AppData\Local\Programs\Python\Python36\lib\site-packages\django\template\loader_tags.py", line 266, in do_extends
    nodelist = parser.parse()
  File "C:\Users\crist\AppData\Local\Programs\Python\Python36\lib\site-packages\django\template\base.py", line 478, in parse
    raise self.error(token, e)
  File "C:\Users\crist\AppData\Local\Programs\Python\Python36\lib\site-packages\django\template\base.py", line 476, in parse
    compiled_result = compile_func(self, token)
  File "C:\Users\crist\AppData\Local\Programs\Python\Python36\lib\site-packages\django\template\loader_tags.py", line 209, in do_block
    nodelist = parser.parse(('endblock',))
  File "C:\Users\crist\AppData\Local\Programs\Python\Python36\lib\site-packages\django\template\base.py", line 472, in parse
    self.invalid_block_tag(token, command, parse_until)
  File "C:\Users\crist\AppData\Local\Programs\Python\Python36\lib\site-packages\django\template\base.py", line 528, in invalid_block_tag
    get_text_list(["'%s'" % p for p in parse_until], 'or'),
django.template.exceptions.TemplateSyntaxError: Invalid block tag on line 27: 'static', expected 'endblock'. Did you forget to register or load this tag?
ERROR:django.request:Internal Server Error: /instabotmv/dashboard/task/new/follow-like/
Traceback (most recent call last):
  File "C:\Users\crist\AppData\Local\Programs\Python\Python36\lib\site-packages\django\template\base.py", line 470, in parse
    compile_func = self.tags[command]
KeyError: 'static2'

During handling of the above exception, another exception occurred:

Traceback (most recent call last):
  File "C:\Users\crist\AppData\Local\Programs\Python\Python36\lib\site-packages\django\core\handlers\exception.py", line 34, in inner
    response = get_response(request)
  File "C:\Users\crist\AppData\Local\Programs\Python\Python36\lib\site-packages\django\core\handlers\base.py", line 126, in _get_response
    response = self.process_exception_by_middleware(e, request)
  File "C:\Users\crist\AppData\Local\Programs\Python\Python36\lib\site-packages\django\core\handlers\base.py", line 124, in _get_response
    response = wrapped_callback(request, *callback_args, **callback_kwargs)
  File "C:\Users\crist\AppData\Local\Programs\Python\Python36\lib\site-packages\django\views\generic\base.py", line 68, in view
    return self.dispatch(request, *args, **kwargs)
  File "C:\Users\crist\AppData\Local\Programs\Python\Python36\lib\site-packages\django\contrib\auth\mixins.py", line 52, in dispatch
    return super().dispatch(request, *args, **kwargs)
  File "C:\Users\crist\AppData\Local\Programs\Python\Python36\lib\site-packages\django\views\generic\base.py", line 88, in dispatch
    return handler(request, *args, **kwargs)
  File "C:\Users\crist\Documents\MYV\mvbotdjango\InstabotMV\views.py", line 296, in get
    return render(request, 'tasks/followAndLike.html', {'Hasgtags': Hasgtags})
  File "C:\Users\crist\AppData\Local\Programs\Python\Python36\lib\site-packages\django\shortcuts.py", line 36, in render
    content = loader.render_to_string(template_name, context, request, using=using)
  File "C:\Users\crist\AppData\Local\Programs\Python\Python36\lib\site-packages\django\template\loader.py", line 61, in render_to_string
    template = get_template(template_name, using=using)
  File "C:\Users\crist\AppData\Local\Programs\Python\Python36\lib\site-packages\django\template\loader.py", line 15, in get_template
    return engine.get_template(template_name)
  File "C:\Users\crist\AppData\Local\Programs\Python\Python36\lib\site-packages\django\template\backends\django.py", line 34, in get_template
    return Template(self.engine.get_template(template_name), self)
  File "C:\Users\crist\AppData\Local\Programs\Python\Python36\lib\site-packages\django\template\engine.py", line 144, in get_template
    template, origin = self.find_template(template_name)
  File "C:\Users\crist\AppData\Local\Programs\Python\Python36\lib\site-packages\django\template\engine.py", line 126, in find_template
    template = loader.get_template(name, skip=skip)
  File "C:\Users\crist\AppData\Local\Programs\Python\Python36\lib\site-packages\django\template\loaders\base.py", line 30, in get_template
    contents, origin, origin.template_name, self.engine,
  File "C:\Users\crist\AppData\Local\Programs\Python\Python36\lib\site-packages\django\template\base.py", line 156, in __init__
    self.nodelist = self.compile_nodelist()
  File "C:\Users\crist\AppData\Local\Programs\Python\Python36\lib\site-packages\django\template\base.py", line 194, in compile_nodelist
    return parser.parse()
  File "C:\Users\crist\AppData\Local\Programs\Python\Python36\lib\site-packages\django\template\base.py", line 478, in parse
    raise self.error(token, e)
  File "C:\Users\crist\AppData\Local\Programs\Python\Python36\lib\site-packages\django\template\base.py", line 476, in parse
    compiled_result = compile_func(self, token)
  File "C:\Users\crist\AppData\Local\Programs\Python\Python36\lib\site-packages\django\template\loader_tags.py", line 266, in do_extends
    nodelist = parser.parse()
  File "C:\Users\crist\AppData\Local\Programs\Python\Python36\lib\site-packages\django\template\base.py", line 478, in parse
    raise self.error(token, e)
  File "C:\Users\crist\AppData\Local\Programs\Python\Python36\lib\site-packages\django\template\base.py", line 476, in parse
    compiled_result = compile_func(self, token)
  File "C:\Users\crist\AppData\Local\Programs\Python\Python36\lib\site-packages\django\template\loader_tags.py", line 209, in do_block
    nodelist = parser.parse(('endblock',))
  File "C:\Users\crist\AppData\Local\Programs\Python\Python36\lib\site-packages\django\template\base.py", line 472, in parse
    self.invalid_block_tag(token, command, parse_until)
  File "C:\Users\crist\AppData\Local\Programs\Python\Python36\lib\site-packages\django\template\base.py", line 528, in invalid_block_tag
    get_text_list(["'%s'" % p for p in parse_until], 'or'),
django.template.exceptions.TemplateSyntaxError: Invalid block tag on line 28: 'static2', expected 'endblock'. Did you forget to register or load this tag?
ERROR:django.request:Internal Server Error: /instabotmv/dashboard/task/new/follow-like/
Traceback (most recent call last):
  File "C:\Users\crist\AppData\Local\Programs\Python\Python36\lib\site-packages\django\template\defaulttags.py", line 1020, in find_library
    return parser.libraries[name]
KeyError: 'static2'

During handling of the above exception, another exception occurred:

Traceback (most recent call last):
  File "C:\Users\crist\AppData\Local\Programs\Python\Python36\lib\site-packages\django\core\handlers\exception.py", line 34, in inner
    response = get_response(request)
  File "C:\Users\crist\AppData\Local\Programs\Python\Python36\lib\site-packages\django\core\handlers\base.py", line 126, in _get_response
    response = self.process_exception_by_middleware(e, request)
  File "C:\Users\crist\AppData\Local\Programs\Python\Python36\lib\site-packages\django\core\handlers\base.py", line 124, in _get_response
    response = wrapped_callback(request, *callback_args, **callback_kwargs)
  File "C:\Users\crist\AppData\Local\Programs\Python\Python36\lib\site-packages\django\views\generic\base.py", line 68, in view
    return self.dispatch(request, *args, **kwargs)
  File "C:\Users\crist\AppData\Local\Programs\Python\Python36\lib\site-packages\django\contrib\auth\mixins.py", line 52, in dispatch
    return super().dispatch(request, *args, **kwargs)
  File "C:\Users\crist\AppData\Local\Programs\Python\Python36\lib\site-packages\django\views\generic\base.py", line 88, in dispatch
    return handler(request, *args, **kwargs)
  File "C:\Users\crist\Documents\MYV\mvbotdjango\InstabotMV\views.py", line 296, in get
    return render(request, 'tasks/followAndLike.html', {'Hasgtags': Hasgtags})
  File "C:\Users\crist\AppData\Local\Programs\Python\Python36\lib\site-packages\django\shortcuts.py", line 36, in render
    content = loader.render_to_string(template_name, context, request, using=using)
  File "C:\Users\crist\AppData\Local\Programs\Python\Python36\lib\site-packages\django\template\loader.py", line 61, in render_to_string
    template = get_template(template_name, using=using)
  File "C:\Users\crist\AppData\Local\Programs\Python\Python36\lib\site-packages\django\template\loader.py", line 15, in get_template
    return engine.get_template(template_name)
  File "C:\Users\crist\AppData\Local\Programs\Python\Python36\lib\site-packages\django\template\backends\django.py", line 34, in get_template
    return Template(self.engine.get_template(template_name), self)
  File "C:\Users\crist\AppData\Local\Programs\Python\Python36\lib\site-packages\django\template\engine.py", line 144, in get_template
    template, origin = self.find_template(template_name)
  File "C:\Users\crist\AppData\Local\Programs\Python\Python36\lib\site-packages\django\template\engine.py", line 126, in find_template
    template = loader.get_template(name, skip=skip)
  File "C:\Users\crist\AppData\Local\Programs\Python\Python36\lib\site-packages\django\template\loaders\base.py", line 30, in get_template
    contents, origin, origin.template_name, self.engine,
  File "C:\Users\crist\AppData\Local\Programs\Python\Python36\lib\site-packages\django\template\base.py", line 156, in __init__
    self.nodelist = self.compile_nodelist()
  File "C:\Users\crist\AppData\Local\Programs\Python\Python36\lib\site-packages\django\template\base.py", line 194, in compile_nodelist
    return parser.parse()
  File "C:\Users\crist\AppData\Local\Programs\Python\Python36\lib\site-packages\django\template\base.py", line 478, in parse
    raise self.error(token, e)
  File "C:\Users\crist\AppData\Local\Programs\Python\Python36\lib\site-packages\django\template\base.py", line 476, in parse
    compiled_result = compile_func(self, token)
  File "C:\Users\crist\AppData\Local\Programs\Python\Python36\lib\site-packages\django\template\loader_tags.py", line 266, in do_extends
    nodelist = parser.parse()
  File "C:\Users\crist\AppData\Local\Programs\Python\Python36\lib\site-packages\django\template\base.py", line 478, in parse
    raise self.error(token, e)
  File "C:\Users\crist\AppData\Local\Programs\Python\Python36\lib\site-packages\django\template\base.py", line 476, in parse
    compiled_result = compile_func(self, token)
  File "C:\Users\crist\AppData\Local\Programs\Python\Python36\lib\site-packages\django\template\defaulttags.py", line 1077, in load
    lib = find_library(parser, name)
  File "C:\Users\crist\AppData\Local\Programs\Python\Python36\lib\site-packages\django\template\defaulttags.py", line 1024, in find_library
    name, "\n".join(sorted(parser.libraries)),
django.template.exceptions.TemplateSyntaxError: 'static2' is not a registered tag library. Must be one of:
admin_list
admin_modify
admin_static
admin_urls
cache
i18n
l10n
log
static
staticfiles
tz
ERROR:django.request:Internal Server Error: /instabotmv/dashboard/task/new/follow-like/
Traceback (most recent call last):
  File "C:\Users\crist\AppData\Local\Programs\Python\Python36\lib\site-packages\django\template\base.py", line 470, in parse
    compile_func = self.tags[command]
KeyError: 'static2'

During handling of the above exception, another exception occurred:

Traceback (most recent call last):
  File "C:\Users\crist\AppData\Local\Programs\Python\Python36\lib\site-packages\django\core\handlers\exception.py", line 34, in inner
    response = get_response(request)
  File "C:\Users\crist\AppData\Local\Programs\Python\Python36\lib\site-packages\django\core\handlers\base.py", line 126, in _get_response
    response = self.process_exception_by_middleware(e, request)
  File "C:\Users\crist\AppData\Local\Programs\Python\Python36\lib\site-packages\django\core\handlers\base.py", line 124, in _get_response
    response = wrapped_callback(request, *callback_args, **callback_kwargs)
  File "C:\Users\crist\AppData\Local\Programs\Python\Python36\lib\site-packages\django\views\generic\base.py", line 68, in view
    return self.dispatch(request, *args, **kwargs)
  File "C:\Users\crist\AppData\Local\Programs\Python\Python36\lib\site-packages\django\contrib\auth\mixins.py", line 52, in dispatch
    return super().dispatch(request, *args, **kwargs)
  File "C:\Users\crist\AppData\Local\Programs\Python\Python36\lib\site-packages\django\views\generic\base.py", line 88, in dispatch
    return handler(request, *args, **kwargs)
  File "C:\Users\crist\Documents\MYV\mvbotdjango\InstabotMV\views.py", line 296, in get
    return render(request, 'tasks/followAndLike.html', {'Hasgtags': Hasgtags})
  File "C:\Users\crist\AppData\Local\Programs\Python\Python36\lib\site-packages\django\shortcuts.py", line 36, in render
    content = loader.render_to_string(template_name, context, request, using=using)
  File "C:\Users\crist\AppData\Local\Programs\Python\Python36\lib\site-packages\django\template\loader.py", line 61, in render_to_string
    template = get_template(template_name, using=using)
  File "C:\Users\crist\AppData\Local\Programs\Python\Python36\lib\site-packages\django\template\loader.py", line 15, in get_template
    return engine.get_template(template_name)
  File "C:\Users\crist\AppData\Local\Programs\Python\Python36\lib\site-packages\django\template\backends\django.py", line 34, in get_template
    return Template(self.engine.get_template(template_name), self)
  File "C:\Users\crist\AppData\Local\Programs\Python\Python36\lib\site-packages\django\template\engine.py", line 144, in get_template
    template, origin = self.find_template(template_name)
  File "C:\Users\crist\AppData\Local\Programs\Python\Python36\lib\site-packages\django\template\engine.py", line 126, in find_template
    template = loader.get_template(name, skip=skip)
  File "C:\Users\crist\AppData\Local\Programs\Python\Python36\lib\site-packages\django\template\loaders\base.py", line 30, in get_template
    contents, origin, origin.template_name, self.engine,
  File "C:\Users\crist\AppData\Local\Programs\Python\Python36\lib\site-packages\django\template\base.py", line 156, in __init__
    self.nodelist = self.compile_nodelist()
  File "C:\Users\crist\AppData\Local\Programs\Python\Python36\lib\site-packages\django\template\base.py", line 194, in compile_nodelist
    return parser.parse()
  File "C:\Users\crist\AppData\Local\Programs\Python\Python36\lib\site-packages\django\template\base.py", line 478, in parse
    raise self.error(token, e)
  File "C:\Users\crist\AppData\Local\Programs\Python\Python36\lib\site-packages\django\template\base.py", line 476, in parse
    compiled_result = compile_func(self, token)
  File "C:\Users\crist\AppData\Local\Programs\Python\Python36\lib\site-packages\django\template\loader_tags.py", line 266, in do_extends
    nodelist = parser.parse()
  File "C:\Users\crist\AppData\Local\Programs\Python\Python36\lib\site-packages\django\template\base.py", line 478, in parse
    raise self.error(token, e)
  File "C:\Users\crist\AppData\Local\Programs\Python\Python36\lib\site-packages\django\template\base.py", line 476, in parse
    compiled_result = compile_func(self, token)
  File "C:\Users\crist\AppData\Local\Programs\Python\Python36\lib\site-packages\django\template\loader_tags.py", line 209, in do_block
    nodelist = parser.parse(('endblock',))
  File "C:\Users\crist\AppData\Local\Programs\Python\Python36\lib\site-packages\django\template\base.py", line 472, in parse
    self.invalid_block_tag(token, command, parse_until)
  File "C:\Users\crist\AppData\Local\Programs\Python\Python36\lib\site-packages\django\template\base.py", line 528, in invalid_block_tag
    get_text_list(["'%s'" % p for p in parse_until], 'or'),
django.template.exceptions.TemplateSyntaxError: Invalid block tag on line 28: 'static2', expected 'endblock'. Did you forget to register or load this tag?
ERROR:django.request:Internal Server Error: /instabotmv/tags/
Traceback (most recent call last):
  File "C:\Users\crist\AppData\Local\Programs\Python\Python36\lib\site-packages\django\core\handlers\exception.py", line 34, in inner
    response = get_response(request)
  File "C:\Users\crist\AppData\Local\Programs\Python\Python36\lib\site-packages\django\core\handlers\base.py", line 126, in _get_response
    response = self.process_exception_by_middleware(e, request)
  File "C:\Users\crist\AppData\Local\Programs\Python\Python36\lib\site-packages\django\core\handlers\base.py", line 124, in _get_response
    response = wrapped_callback(request, *callback_args, **callback_kwargs)
  File "C:\Users\crist\Documents\MYV\mvbotdjango\InstabotMV\views.py", line 276, in tags
    tags= List_Tag.objects.filter(category=category)
  File "C:\Users\crist\AppData\Local\Programs\Python\Python36\lib\site-packages\django\db\models\manager.py", line 82, in manager_method
    return getattr(self.get_queryset(), name)(*args, **kwargs)
  File "C:\Users\crist\AppData\Local\Programs\Python\Python36\lib\site-packages\django\db\models\query.py", line 844, in filter
    return self._filter_or_exclude(False, *args, **kwargs)
  File "C:\Users\crist\AppData\Local\Programs\Python\Python36\lib\site-packages\django\db\models\query.py", line 862, in _filter_or_exclude
    clone.query.add_q(Q(*args, **kwargs))
  File "C:\Users\crist\AppData\Local\Programs\Python\Python36\lib\site-packages\django\db\models\sql\query.py", line 1263, in add_q
    clause, _ = self._add_q(q_object, self.used_aliases)
  File "C:\Users\crist\AppData\Local\Programs\Python\Python36\lib\site-packages\django\db\models\sql\query.py", line 1287, in _add_q
    split_subq=split_subq,
  File "C:\Users\crist\AppData\Local\Programs\Python\Python36\lib\site-packages\django\db\models\sql\query.py", line 1225, in build_filter
    condition = self.build_lookup(lookups, col, value)
  File "C:\Users\crist\AppData\Local\Programs\Python\Python36\lib\site-packages\django\db\models\sql\query.py", line 1096, in build_lookup
    lookup = lookup_class(lhs, rhs)
  File "C:\Users\crist\AppData\Local\Programs\Python\Python36\lib\site-packages\django\db\models\lookups.py", line 20, in __init__
    self.rhs = self.get_prep_lookup()
  File "C:\Users\crist\AppData\Local\Programs\Python\Python36\lib\site-packages\django\db\models\fields\related_lookups.py", line 115, in get_prep_lookup
    self.rhs = target_field.get_prep_value(self.rhs)
  File "C:\Users\crist\AppData\Local\Programs\Python\Python36\lib\site-packages\django\db\models\fields\__init__.py", line 965, in get_prep_value
    return int(value)
ValueError: invalid literal for int() with base 10: 'Select your audience'
WARNING:django.request:Not Found: /favicon.ico
WARNING:django.request:Not Found: /favicon.ico
WARNING:django.request:Not Found: /instabotmv/
WARNING:django.request:Not Found: /favicon.ico
WARNING:django.request:Not Found: /instabotmv/dashboard/task/new/follow-like/2
WARNING:django.request:Not Found: /instabotmv/dashboard/task/new/follow-like/2
WARNING:django.request:Not Found: /instabotmv/dashboard/task/new/follow-like/3
WARNING:django.request:Not Found: /favicon.ico
ERROR:django.request:Internal Server Error: /instabotmv/dashboard/task/new/follow-like/
Traceback (most recent call last):
  File "C:\Users\crist\AppData\Local\Programs\Python\Python36\lib\site-packages\django\core\handlers\exception.py", line 34, in inner
    response = get_response(request)
  File "C:\Users\crist\AppData\Local\Programs\Python\Python36\lib\site-packages\django\core\handlers\base.py", line 126, in _get_response
    response = self.process_exception_by_middleware(e, request)
  File "C:\Users\crist\AppData\Local\Programs\Python\Python36\lib\site-packages\django\core\handlers\base.py", line 124, in _get_response
    response = wrapped_callback(request, *callback_args, **callback_kwargs)
  File "C:\Users\crist\AppData\Local\Programs\Python\Python36\lib\site-packages\django\views\generic\base.py", line 68, in view
    return self.dispatch(request, *args, **kwargs)
  File "C:\Users\crist\AppData\Local\Programs\Python\Python36\lib\site-packages\django\contrib\auth\mixins.py", line 52, in dispatch
    return super().dispatch(request, *args, **kwargs)
  File "C:\Users\crist\AppData\Local\Programs\Python\Python36\lib\site-packages\django\views\generic\base.py", line 88, in dispatch
    return handler(request, *args, **kwargs)
  File "C:\Users\crist\Documents\MYV\mvbotdjango\InstabotMV\views.py", line 296, in get
    return render(request, 'tasks/followAndLike.html', {'Hasgtags': Hasgtags})
  File "C:\Users\crist\AppData\Local\Programs\Python\Python36\lib\site-packages\django\shortcuts.py", line 36, in render
    content = loader.render_to_string(template_name, context, request, using=using)
  File "C:\Users\crist\AppData\Local\Programs\Python\Python36\lib\site-packages\django\template\loader.py", line 62, in render_to_string
    return template.render(context, request)
  File "C:\Users\crist\AppData\Local\Programs\Python\Python36\lib\site-packages\django\template\backends\django.py", line 61, in render
    return self.template.render(context)
  File "C:\Users\crist\AppData\Local\Programs\Python\Python36\lib\site-packages\django\template\base.py", line 171, in render
    return self._render(context)
  File "C:\Users\crist\AppData\Local\Programs\Python\Python36\lib\site-packages\django\template\base.py", line 163, in _render
    return self.nodelist.render(context)
  File "C:\Users\crist\AppData\Local\Programs\Python\Python36\lib\site-packages\django\template\base.py", line 937, in render
    bit = node.render_annotated(context)
  File "C:\Users\crist\AppData\Local\Programs\Python\Python36\lib\site-packages\django\template\base.py", line 904, in render_annotated
    return self.render(context)
  File "C:\Users\crist\AppData\Local\Programs\Python\Python36\lib\site-packages\django\template\loader_tags.py", line 150, in render
    return compiled_parent._render(context)
  File "C:\Users\crist\AppData\Local\Programs\Python\Python36\lib\site-packages\django\template\base.py", line 163, in _render
    return self.nodelist.render(context)
  File "C:\Users\crist\AppData\Local\Programs\Python\Python36\lib\site-packages\django\template\base.py", line 937, in render
    bit = node.render_annotated(context)
  File "C:\Users\crist\AppData\Local\Programs\Python\Python36\lib\site-packages\django\template\base.py", line 904, in render_annotated
    return self.render(context)
  File "C:\Users\crist\AppData\Local\Programs\Python\Python36\lib\site-packages\django\template\loader_tags.py", line 150, in render
    return compiled_parent._render(context)
  File "C:\Users\crist\AppData\Local\Programs\Python\Python36\lib\site-packages\django\template\base.py", line 163, in _render
    return self.nodelist.render(context)
  File "C:\Users\crist\AppData\Local\Programs\Python\Python36\lib\site-packages\django\template\base.py", line 937, in render
    bit = node.render_annotated(context)
  File "C:\Users\crist\AppData\Local\Programs\Python\Python36\lib\site-packages\django\template\base.py", line 904, in render_annotated
    return self.render(context)
  File "C:\Users\crist\AppData\Local\Programs\Python\Python36\lib\site-packages\django\template\loader_tags.py", line 62, in render
    result = block.nodelist.render(context)
  File "C:\Users\crist\AppData\Local\Programs\Python\Python36\lib\site-packages\django\template\base.py", line 937, in render
    bit = node.render_annotated(context)
  File "C:\Users\crist\AppData\Local\Programs\Python\Python36\lib\site-packages\django\template\base.py", line 904, in render_annotated
    return self.render(context)
  File "C:\Users\crist\AppData\Local\Programs\Python\Python36\lib\site-packages\django\template\defaulttags.py", line 442, in render
    url = reverse(view_name, args=args, kwargs=kwargs, current_app=current_app)
  File "C:\Users\crist\AppData\Local\Programs\Python\Python36\lib\site-packages\django\urls\base.py", line 90, in reverse
    return iri_to_uri(resolver._reverse_with_prefix(view, prefix, *args, **kwargs))
  File "C:\Users\crist\AppData\Local\Programs\Python\Python36\lib\site-packages\django\urls\resolvers.py", line 622, in _reverse_with_prefix
    raise NoReverseMatch(msg)
django.urls.exceptions.NoReverseMatch: Reverse for 'tags' with no arguments not found. 1 pattern(s) tried: ['instabotmv\\/tags/(?P<produ>\\w{0,50})/$']
ERROR:django.request:Internal Server Error: /instabotmv/dashboard/task/new/follow-like/
Traceback (most recent call last):
  File "C:\Users\crist\AppData\Local\Programs\Python\Python36\lib\site-packages\django\core\handlers\exception.py", line 34, in inner
    response = get_response(request)
  File "C:\Users\crist\AppData\Local\Programs\Python\Python36\lib\site-packages\django\core\handlers\base.py", line 126, in _get_response
    response = self.process_exception_by_middleware(e, request)
  File "C:\Users\crist\AppData\Local\Programs\Python\Python36\lib\site-packages\django\core\handlers\base.py", line 124, in _get_response
    response = wrapped_callback(request, *callback_args, **callback_kwargs)
  File "C:\Users\crist\AppData\Local\Programs\Python\Python36\lib\site-packages\django\views\generic\base.py", line 68, in view
    return self.dispatch(request, *args, **kwargs)
  File "C:\Users\crist\AppData\Local\Programs\Python\Python36\lib\site-packages\django\contrib\auth\mixins.py", line 52, in dispatch
    return super().dispatch(request, *args, **kwargs)
  File "C:\Users\crist\AppData\Local\Programs\Python\Python36\lib\site-packages\django\views\generic\base.py", line 88, in dispatch
    return handler(request, *args, **kwargs)
  File "C:\Users\crist\Documents\MYV\mvbotdjango\InstabotMV\views.py", line 296, in get
    return render(request, 'tasks/followAndLike.html', {'Hasgtags': Hasgtags})
  File "C:\Users\crist\AppData\Local\Programs\Python\Python36\lib\site-packages\django\shortcuts.py", line 36, in render
    content = loader.render_to_string(template_name, context, request, using=using)
  File "C:\Users\crist\AppData\Local\Programs\Python\Python36\lib\site-packages\django\template\loader.py", line 62, in render_to_string
    return template.render(context, request)
  File "C:\Users\crist\AppData\Local\Programs\Python\Python36\lib\site-packages\django\template\backends\django.py", line 61, in render
    return self.template.render(context)
  File "C:\Users\crist\AppData\Local\Programs\Python\Python36\lib\site-packages\django\template\base.py", line 171, in render
    return self._render(context)
  File "C:\Users\crist\AppData\Local\Programs\Python\Python36\lib\site-packages\django\template\base.py", line 163, in _render
    return self.nodelist.render(context)
  File "C:\Users\crist\AppData\Local\Programs\Python\Python36\lib\site-packages\django\template\base.py", line 937, in render
    bit = node.render_annotated(context)
  File "C:\Users\crist\AppData\Local\Programs\Python\Python36\lib\site-packages\django\template\base.py", line 904, in render_annotated
    return self.render(context)
  File "C:\Users\crist\AppData\Local\Programs\Python\Python36\lib\site-packages\django\template\loader_tags.py", line 150, in render
    return compiled_parent._render(context)
  File "C:\Users\crist\AppData\Local\Programs\Python\Python36\lib\site-packages\django\template\base.py", line 163, in _render
    return self.nodelist.render(context)
  File "C:\Users\crist\AppData\Local\Programs\Python\Python36\lib\site-packages\django\template\base.py", line 937, in render
    bit = node.render_annotated(context)
  File "C:\Users\crist\AppData\Local\Programs\Python\Python36\lib\site-packages\django\template\base.py", line 904, in render_annotated
    return self.render(context)
  File "C:\Users\crist\AppData\Local\Programs\Python\Python36\lib\site-packages\django\template\loader_tags.py", line 150, in render
    return compiled_parent._render(context)
  File "C:\Users\crist\AppData\Local\Programs\Python\Python36\lib\site-packages\django\template\base.py", line 163, in _render
    return self.nodelist.render(context)
  File "C:\Users\crist\AppData\Local\Programs\Python\Python36\lib\site-packages\django\template\base.py", line 937, in render
    bit = node.render_annotated(context)
  File "C:\Users\crist\AppData\Local\Programs\Python\Python36\lib\site-packages\django\template\base.py", line 904, in render_annotated
    return self.render(context)
  File "C:\Users\crist\AppData\Local\Programs\Python\Python36\lib\site-packages\django\template\loader_tags.py", line 62, in render
    result = block.nodelist.render(context)
  File "C:\Users\crist\AppData\Local\Programs\Python\Python36\lib\site-packages\django\template\base.py", line 937, in render
    bit = node.render_annotated(context)
  File "C:\Users\crist\AppData\Local\Programs\Python\Python36\lib\site-packages\django\template\base.py", line 904, in render_annotated
    return self.render(context)
  File "C:\Users\crist\AppData\Local\Programs\Python\Python36\lib\site-packages\django\template\defaulttags.py", line 442, in render
    url = reverse(view_name, args=args, kwargs=kwargs, current_app=current_app)
  File "C:\Users\crist\AppData\Local\Programs\Python\Python36\lib\site-packages\django\urls\base.py", line 90, in reverse
    return iri_to_uri(resolver._reverse_with_prefix(view, prefix, *args, **kwargs))
  File "C:\Users\crist\AppData\Local\Programs\Python\Python36\lib\site-packages\django\urls\resolvers.py", line 622, in _reverse_with_prefix
    raise NoReverseMatch(msg)
django.urls.exceptions.NoReverseMatch: Reverse for 'tags' with no arguments not found. 1 pattern(s) tried: ['instabotmv\\/tags/(?P<category>\\w{0,50})/$']
ERROR:django.request:Internal Server Error: /instabotmv/dashboard/task/new/follow-like/
Traceback (most recent call last):
  File "C:\Users\crist\AppData\Local\Programs\Python\Python36\lib\site-packages\django\core\handlers\exception.py", line 34, in inner
    response = get_response(request)
  File "C:\Users\crist\AppData\Local\Programs\Python\Python36\lib\site-packages\django\core\handlers\base.py", line 126, in _get_response
    response = self.process_exception_by_middleware(e, request)
  File "C:\Users\crist\AppData\Local\Programs\Python\Python36\lib\site-packages\django\core\handlers\base.py", line 124, in _get_response
    response = wrapped_callback(request, *callback_args, **callback_kwargs)
  File "C:\Users\crist\AppData\Local\Programs\Python\Python36\lib\site-packages\django\views\generic\base.py", line 68, in view
    return self.dispatch(request, *args, **kwargs)
  File "C:\Users\crist\AppData\Local\Programs\Python\Python36\lib\site-packages\django\contrib\auth\mixins.py", line 52, in dispatch
    return super().dispatch(request, *args, **kwargs)
  File "C:\Users\crist\AppData\Local\Programs\Python\Python36\lib\site-packages\django\views\generic\base.py", line 88, in dispatch
    return handler(request, *args, **kwargs)
  File "C:\Users\crist\Documents\MYV\mvbotdjango\InstabotMV\views.py", line 296, in get
    return render(request, 'tasks/followAndLike.html', {'Hasgtags': Hasgtags})
  File "C:\Users\crist\AppData\Local\Programs\Python\Python36\lib\site-packages\django\shortcuts.py", line 36, in render
    content = loader.render_to_string(template_name, context, request, using=using)
  File "C:\Users\crist\AppData\Local\Programs\Python\Python36\lib\site-packages\django\template\loader.py", line 62, in render_to_string
    return template.render(context, request)
  File "C:\Users\crist\AppData\Local\Programs\Python\Python36\lib\site-packages\django\template\backends\django.py", line 61, in render
    return self.template.render(context)
  File "C:\Users\crist\AppData\Local\Programs\Python\Python36\lib\site-packages\django\template\base.py", line 171, in render
    return self._render(context)
  File "C:\Users\crist\AppData\Local\Programs\Python\Python36\lib\site-packages\django\template\base.py", line 163, in _render
    return self.nodelist.render(context)
  File "C:\Users\crist\AppData\Local\Programs\Python\Python36\lib\site-packages\django\template\base.py", line 937, in render
    bit = node.render_annotated(context)
  File "C:\Users\crist\AppData\Local\Programs\Python\Python36\lib\site-packages\django\template\base.py", line 904, in render_annotated
    return self.render(context)
  File "C:\Users\crist\AppData\Local\Programs\Python\Python36\lib\site-packages\django\template\loader_tags.py", line 150, in render
    return compiled_parent._render(context)
  File "C:\Users\crist\AppData\Local\Programs\Python\Python36\lib\site-packages\django\template\base.py", line 163, in _render
    return self.nodelist.render(context)
  File "C:\Users\crist\AppData\Local\Programs\Python\Python36\lib\site-packages\django\template\base.py", line 937, in render
    bit = node.render_annotated(context)
  File "C:\Users\crist\AppData\Local\Programs\Python\Python36\lib\site-packages\django\template\base.py", line 904, in render_annotated
    return self.render(context)
  File "C:\Users\crist\AppData\Local\Programs\Python\Python36\lib\site-packages\django\template\loader_tags.py", line 150, in render
    return compiled_parent._render(context)
  File "C:\Users\crist\AppData\Local\Programs\Python\Python36\lib\site-packages\django\template\base.py", line 163, in _render
    return self.nodelist.render(context)
  File "C:\Users\crist\AppData\Local\Programs\Python\Python36\lib\site-packages\django\template\base.py", line 937, in render
    bit = node.render_annotated(context)
  File "C:\Users\crist\AppData\Local\Programs\Python\Python36\lib\site-packages\django\template\base.py", line 904, in render_annotated
    return self.render(context)
  File "C:\Users\crist\AppData\Local\Programs\Python\Python36\lib\site-packages\django\template\loader_tags.py", line 62, in render
    result = block.nodelist.render(context)
  File "C:\Users\crist\AppData\Local\Programs\Python\Python36\lib\site-packages\django\template\base.py", line 937, in render
    bit = node.render_annotated(context)
  File "C:\Users\crist\AppData\Local\Programs\Python\Python36\lib\site-packages\django\template\base.py", line 904, in render_annotated
    return self.render(context)
  File "C:\Users\crist\AppData\Local\Programs\Python\Python36\lib\site-packages\django\template\defaulttags.py", line 442, in render
    url = reverse(view_name, args=args, kwargs=kwargs, current_app=current_app)
  File "C:\Users\crist\AppData\Local\Programs\Python\Python36\lib\site-packages\django\urls\base.py", line 90, in reverse
    return iri_to_uri(resolver._reverse_with_prefix(view, prefix, *args, **kwargs))
  File "C:\Users\crist\AppData\Local\Programs\Python\Python36\lib\site-packages\django\urls\resolvers.py", line 622, in _reverse_with_prefix
    raise NoReverseMatch(msg)
django.urls.exceptions.NoReverseMatch: Reverse for 'tags' with no arguments not found. 1 pattern(s) tried: ['instabotmv\\/tags/(?P<category>\\w{0,50})/$']
ERROR:django.request:Internal Server Error: /instabotmv/dashboard/task/new/follow-like/
Traceback (most recent call last):
  File "C:\Users\crist\AppData\Local\Programs\Python\Python36\lib\site-packages\django\core\handlers\exception.py", line 34, in inner
    response = get_response(request)
  File "C:\Users\crist\AppData\Local\Programs\Python\Python36\lib\site-packages\django\core\handlers\base.py", line 126, in _get_response
    response = self.process_exception_by_middleware(e, request)
  File "C:\Users\crist\AppData\Local\Programs\Python\Python36\lib\site-packages\django\core\handlers\base.py", line 124, in _get_response
    response = wrapped_callback(request, *callback_args, **callback_kwargs)
  File "C:\Users\crist\AppData\Local\Programs\Python\Python36\lib\site-packages\django\views\generic\base.py", line 68, in view
    return self.dispatch(request, *args, **kwargs)
  File "C:\Users\crist\AppData\Local\Programs\Python\Python36\lib\site-packages\django\contrib\auth\mixins.py", line 52, in dispatch
    return super().dispatch(request, *args, **kwargs)
  File "C:\Users\crist\AppData\Local\Programs\Python\Python36\lib\site-packages\django\views\generic\base.py", line 88, in dispatch
    return handler(request, *args, **kwargs)
  File "C:\Users\crist\Documents\MYV\mvbotdjango\InstabotMV\views.py", line 296, in get
    return render(request, 'tasks/followAndLike.html', {'Hasgtags': Hasgtags})
  File "C:\Users\crist\AppData\Local\Programs\Python\Python36\lib\site-packages\django\shortcuts.py", line 36, in render
    content = loader.render_to_string(template_name, context, request, using=using)
  File "C:\Users\crist\AppData\Local\Programs\Python\Python36\lib\site-packages\django\template\loader.py", line 62, in render_to_string
    return template.render(context, request)
  File "C:\Users\crist\AppData\Local\Programs\Python\Python36\lib\site-packages\django\template\backends\django.py", line 61, in render
    return self.template.render(context)
  File "C:\Users\crist\AppData\Local\Programs\Python\Python36\lib\site-packages\django\template\base.py", line 171, in render
    return self._render(context)
  File "C:\Users\crist\AppData\Local\Programs\Python\Python36\lib\site-packages\django\template\base.py", line 163, in _render
    return self.nodelist.render(context)
  File "C:\Users\crist\AppData\Local\Programs\Python\Python36\lib\site-packages\django\template\base.py", line 937, in render
    bit = node.render_annotated(context)
  File "C:\Users\crist\AppData\Local\Programs\Python\Python36\lib\site-packages\django\template\base.py", line 904, in render_annotated
    return self.render(context)
  File "C:\Users\crist\AppData\Local\Programs\Python\Python36\lib\site-packages\django\template\loader_tags.py", line 150, in render
    return compiled_parent._render(context)
  File "C:\Users\crist\AppData\Local\Programs\Python\Python36\lib\site-packages\django\template\base.py", line 163, in _render
    return self.nodelist.render(context)
  File "C:\Users\crist\AppData\Local\Programs\Python\Python36\lib\site-packages\django\template\base.py", line 937, in render
    bit = node.render_annotated(context)
  File "C:\Users\crist\AppData\Local\Programs\Python\Python36\lib\site-packages\django\template\base.py", line 904, in render_annotated
    return self.render(context)
  File "C:\Users\crist\AppData\Local\Programs\Python\Python36\lib\site-packages\django\template\loader_tags.py", line 150, in render
    return compiled_parent._render(context)
  File "C:\Users\crist\AppData\Local\Programs\Python\Python36\lib\site-packages\django\template\base.py", line 163, in _render
    return self.nodelist.render(context)
  File "C:\Users\crist\AppData\Local\Programs\Python\Python36\lib\site-packages\django\template\base.py", line 937, in render
    bit = node.render_annotated(context)
  File "C:\Users\crist\AppData\Local\Programs\Python\Python36\lib\site-packages\django\template\base.py", line 904, in render_annotated
    return self.render(context)
  File "C:\Users\crist\AppData\Local\Programs\Python\Python36\lib\site-packages\django\template\loader_tags.py", line 62, in render
    result = block.nodelist.render(context)
  File "C:\Users\crist\AppData\Local\Programs\Python\Python36\lib\site-packages\django\template\base.py", line 937, in render
    bit = node.render_annotated(context)
  File "C:\Users\crist\AppData\Local\Programs\Python\Python36\lib\site-packages\django\template\base.py", line 904, in render_annotated
    return self.render(context)
  File "C:\Users\crist\AppData\Local\Programs\Python\Python36\lib\site-packages\django\template\defaulttags.py", line 442, in render
    url = reverse(view_name, args=args, kwargs=kwargs, current_app=current_app)
  File "C:\Users\crist\AppData\Local\Programs\Python\Python36\lib\site-packages\django\urls\base.py", line 90, in reverse
    return iri_to_uri(resolver._reverse_with_prefix(view, prefix, *args, **kwargs))
  File "C:\Users\crist\AppData\Local\Programs\Python\Python36\lib\site-packages\django\urls\resolvers.py", line 622, in _reverse_with_prefix
    raise NoReverseMatch(msg)
django.urls.exceptions.NoReverseMatch: Reverse for 'tags' with no arguments not found. 1 pattern(s) tried: ['instabotmv\\/tags/(?P<category>\\w{0,50})/$']
WARNING:django.request:Not Found: /instabotmv/tags/
WARNING:django.request:Not Found: /instabotmv/
ERROR:django.request:Internal Server Error: /instabotmv/dashboard/task/new/follow-like/
Traceback (most recent call last):
  File "C:\Users\crist\AppData\Local\Programs\Python\Python36\lib\site-packages\django\core\handlers\exception.py", line 34, in inner
    response = get_response(request)
  File "C:\Users\crist\AppData\Local\Programs\Python\Python36\lib\site-packages\django\core\handlers\base.py", line 126, in _get_response
    response = self.process_exception_by_middleware(e, request)
  File "C:\Users\crist\AppData\Local\Programs\Python\Python36\lib\site-packages\django\core\handlers\base.py", line 124, in _get_response
    response = wrapped_callback(request, *callback_args, **callback_kwargs)
  File "C:\Users\crist\AppData\Local\Programs\Python\Python36\lib\site-packages\django\views\generic\base.py", line 68, in view
    return self.dispatch(request, *args, **kwargs)
  File "C:\Users\crist\AppData\Local\Programs\Python\Python36\lib\site-packages\django\contrib\auth\mixins.py", line 52, in dispatch
    return super().dispatch(request, *args, **kwargs)
  File "C:\Users\crist\AppData\Local\Programs\Python\Python36\lib\site-packages\django\views\generic\base.py", line 88, in dispatch
    return handler(request, *args, **kwargs)
  File "C:\Users\crist\Documents\MYV\mvbotdjango\InstabotMV\views.py", line 296, in get
    return render(request, 'tasks/followAndLike.html', {'Hasgtags': Hasgtags})
  File "C:\Users\crist\AppData\Local\Programs\Python\Python36\lib\site-packages\django\shortcuts.py", line 36, in render
    content = loader.render_to_string(template_name, context, request, using=using)
  File "C:\Users\crist\AppData\Local\Programs\Python\Python36\lib\site-packages\django\template\loader.py", line 62, in render_to_string
    return template.render(context, request)
  File "C:\Users\crist\AppData\Local\Programs\Python\Python36\lib\site-packages\django\template\backends\django.py", line 61, in render
    return self.template.render(context)
  File "C:\Users\crist\AppData\Local\Programs\Python\Python36\lib\site-packages\django\template\base.py", line 171, in render
    return self._render(context)
  File "C:\Users\crist\AppData\Local\Programs\Python\Python36\lib\site-packages\django\template\base.py", line 163, in _render
    return self.nodelist.render(context)
  File "C:\Users\crist\AppData\Local\Programs\Python\Python36\lib\site-packages\django\template\base.py", line 937, in render
    bit = node.render_annotated(context)
  File "C:\Users\crist\AppData\Local\Programs\Python\Python36\lib\site-packages\django\template\base.py", line 904, in render_annotated
    return self.render(context)
  File "C:\Users\crist\AppData\Local\Programs\Python\Python36\lib\site-packages\django\template\loader_tags.py", line 150, in render
    return compiled_parent._render(context)
  File "C:\Users\crist\AppData\Local\Programs\Python\Python36\lib\site-packages\django\template\base.py", line 163, in _render
    return self.nodelist.render(context)
  File "C:\Users\crist\AppData\Local\Programs\Python\Python36\lib\site-packages\django\template\base.py", line 937, in render
    bit = node.render_annotated(context)
  File "C:\Users\crist\AppData\Local\Programs\Python\Python36\lib\site-packages\django\template\base.py", line 904, in render_annotated
    return self.render(context)
  File "C:\Users\crist\AppData\Local\Programs\Python\Python36\lib\site-packages\django\template\loader_tags.py", line 150, in render
    return compiled_parent._render(context)
  File "C:\Users\crist\AppData\Local\Programs\Python\Python36\lib\site-packages\django\template\base.py", line 163, in _render
    return self.nodelist.render(context)
  File "C:\Users\crist\AppData\Local\Programs\Python\Python36\lib\site-packages\django\template\base.py", line 937, in render
    bit = node.render_annotated(context)
  File "C:\Users\crist\AppData\Local\Programs\Python\Python36\lib\site-packages\django\template\base.py", line 904, in render_annotated
    return self.render(context)
  File "C:\Users\crist\AppData\Local\Programs\Python\Python36\lib\site-packages\django\template\loader_tags.py", line 62, in render
    result = block.nodelist.render(context)
  File "C:\Users\crist\AppData\Local\Programs\Python\Python36\lib\site-packages\django\template\base.py", line 937, in render
    bit = node.render_annotated(context)
  File "C:\Users\crist\AppData\Local\Programs\Python\Python36\lib\site-packages\django\template\base.py", line 904, in render_annotated
    return self.render(context)
  File "C:\Users\crist\AppData\Local\Programs\Python\Python36\lib\site-packages\django\template\defaulttags.py", line 442, in render
    url = reverse(view_name, args=args, kwargs=kwargs, current_app=current_app)
  File "C:\Users\crist\AppData\Local\Programs\Python\Python36\lib\site-packages\django\urls\base.py", line 90, in reverse
    return iri_to_uri(resolver._reverse_with_prefix(view, prefix, *args, **kwargs))
  File "C:\Users\crist\AppData\Local\Programs\Python\Python36\lib\site-packages\django\urls\resolvers.py", line 622, in _reverse_with_prefix
    raise NoReverseMatch(msg)
django.urls.exceptions.NoReverseMatch: Reverse for 'tags' with no arguments not found. 1 pattern(s) tried: ['instabotmv\\/tags/(?P<id_tag>\\d+)/$']
ERROR:django.request:Internal Server Error: /instabotmv/dashboard/task/new/follow-like/
Traceback (most recent call last):
  File "C:\Users\crist\AppData\Local\Programs\Python\Python36\lib\site-packages\django\core\handlers\exception.py", line 34, in inner
    response = get_response(request)
  File "C:\Users\crist\AppData\Local\Programs\Python\Python36\lib\site-packages\django\core\handlers\base.py", line 126, in _get_response
    response = self.process_exception_by_middleware(e, request)
  File "C:\Users\crist\AppData\Local\Programs\Python\Python36\lib\site-packages\django\core\handlers\base.py", line 124, in _get_response
    response = wrapped_callback(request, *callback_args, **callback_kwargs)
  File "C:\Users\crist\AppData\Local\Programs\Python\Python36\lib\site-packages\django\views\generic\base.py", line 68, in view
    return self.dispatch(request, *args, **kwargs)
  File "C:\Users\crist\AppData\Local\Programs\Python\Python36\lib\site-packages\django\contrib\auth\mixins.py", line 52, in dispatch
    return super().dispatch(request, *args, **kwargs)
  File "C:\Users\crist\AppData\Local\Programs\Python\Python36\lib\site-packages\django\views\generic\base.py", line 88, in dispatch
    return handler(request, *args, **kwargs)
  File "C:\Users\crist\Documents\MYV\mvbotdjango\InstabotMV\views.py", line 296, in get
    return render(request, 'tasks/followAndLike.html', {'Hasgtags': Hasgtags})
  File "C:\Users\crist\AppData\Local\Programs\Python\Python36\lib\site-packages\django\shortcuts.py", line 36, in render
    content = loader.render_to_string(template_name, context, request, using=using)
  File "C:\Users\crist\AppData\Local\Programs\Python\Python36\lib\site-packages\django\template\loader.py", line 62, in render_to_string
    return template.render(context, request)
  File "C:\Users\crist\AppData\Local\Programs\Python\Python36\lib\site-packages\django\template\backends\django.py", line 61, in render
    return self.template.render(context)
  File "C:\Users\crist\AppData\Local\Programs\Python\Python36\lib\site-packages\django\template\base.py", line 171, in render
    return self._render(context)
  File "C:\Users\crist\AppData\Local\Programs\Python\Python36\lib\site-packages\django\template\base.py", line 163, in _render
    return self.nodelist.render(context)
  File "C:\Users\crist\AppData\Local\Programs\Python\Python36\lib\site-packages\django\template\base.py", line 937, in render
    bit = node.render_annotated(context)
  File "C:\Users\crist\AppData\Local\Programs\Python\Python36\lib\site-packages\django\template\base.py", line 904, in render_annotated
    return self.render(context)
  File "C:\Users\crist\AppData\Local\Programs\Python\Python36\lib\site-packages\django\template\loader_tags.py", line 150, in render
    return compiled_parent._render(context)
  File "C:\Users\crist\AppData\Local\Programs\Python\Python36\lib\site-packages\django\template\base.py", line 163, in _render
    return self.nodelist.render(context)
  File "C:\Users\crist\AppData\Local\Programs\Python\Python36\lib\site-packages\django\template\base.py", line 937, in render
    bit = node.render_annotated(context)
  File "C:\Users\crist\AppData\Local\Programs\Python\Python36\lib\site-packages\django\template\base.py", line 904, in render_annotated
    return self.render(context)
  File "C:\Users\crist\AppData\Local\Programs\Python\Python36\lib\site-packages\django\template\loader_tags.py", line 150, in render
    return compiled_parent._render(context)
  File "C:\Users\crist\AppData\Local\Programs\Python\Python36\lib\site-packages\django\template\base.py", line 163, in _render
    return self.nodelist.render(context)
  File "C:\Users\crist\AppData\Local\Programs\Python\Python36\lib\site-packages\django\template\base.py", line 937, in render
    bit = node.render_annotated(context)
  File "C:\Users\crist\AppData\Local\Programs\Python\Python36\lib\site-packages\django\template\base.py", line 904, in render_annotated
    return self.render(context)
  File "C:\Users\crist\AppData\Local\Programs\Python\Python36\lib\site-packages\django\template\loader_tags.py", line 62, in render
    result = block.nodelist.render(context)
  File "C:\Users\crist\AppData\Local\Programs\Python\Python36\lib\site-packages\django\template\base.py", line 937, in render
    bit = node.render_annotated(context)
  File "C:\Users\crist\AppData\Local\Programs\Python\Python36\lib\site-packages\django\template\base.py", line 904, in render_annotated
    return self.render(context)
  File "C:\Users\crist\AppData\Local\Programs\Python\Python36\lib\site-packages\django\template\defaulttags.py", line 442, in render
    url = reverse(view_name, args=args, kwargs=kwargs, current_app=current_app)
  File "C:\Users\crist\AppData\Local\Programs\Python\Python36\lib\site-packages\django\urls\base.py", line 90, in reverse
    return iri_to_uri(resolver._reverse_with_prefix(view, prefix, *args, **kwargs))
  File "C:\Users\crist\AppData\Local\Programs\Python\Python36\lib\site-packages\django\urls\resolvers.py", line 622, in _reverse_with_prefix
    raise NoReverseMatch(msg)
django.urls.exceptions.NoReverseMatch: Reverse for 'tags' with no arguments not found. 1 pattern(s) tried: ['instabotmv\\/tags/(?P<id_tag>\\d+)/$']
WARNING:django.request:Not Found: /'instabotmv/tags/Select your audience/
WARNING:django.request:Not Found: /'instabotmv/tags/Select your audience/
WARNING:django.request:Not Found: /'instabotmv/tags/People using most popular tags/
WARNING:django.request:Not Found: /'instabotmv/tags/Selfie HandSome Beutiful/
WARNING:django.request:Not Found: /'instabotmv/tags/[object HTMLSelectElement]/
WARNING:django.request:Not Found: /'instabotmv/tags/Select your audience/
WARNING:django.request:Not Found: /'instabotmv/tags//
WARNING:django.request:Not Found: /'instabotmv/tags/undefined/
WARNING:django.request:Not Found: /'instabotmv/tags/undefined/
WARNING:django.request:Not Found: /'instabotmv/tags/Select your audience/
WARNING:django.request:Not Found: /'instabotmv/tags/1/
WARNING:django.request:Not Found: /instabotmv/tags/Select your audience/
WARNING:django.request:Not Found: /instabotmv/tags/People using most popular tags/
WARNING:django.request:Not Found: /instabotmv/tags/Select your audience/
WARNING:django.request:Not Found: /instabotmv/tags/[object HTMLSelectElement]/
WARNING:django.request:Not Found: /instabotmv/tags/[object HTMLSelectElement]/
WARNING:django.request:Not Found: /instabotmv/tags/Select your audience/
WARNING:django.request:Not Found: /instabotmv/tags/null/
WARNING:django.request:Not Found: /instabotmv/tags/[object HTMLSelectElement]/
ERROR:django.request:Internal Server Error: /instabotmv/tags/1/
Traceback (most recent call last):
  File "C:\Users\crist\AppData\Local\Programs\Python\Python36\lib\site-packages\django\core\handlers\exception.py", line 34, in inner
    response = get_response(request)
  File "C:\Users\crist\AppData\Local\Programs\Python\Python36\lib\site-packages\django\core\handlers\base.py", line 126, in _get_response
    response = self.process_exception_by_middleware(e, request)
  File "C:\Users\crist\AppData\Local\Programs\Python\Python36\lib\site-packages\django\core\handlers\base.py", line 124, in _get_response
    response = wrapped_callback(request, *callback_args, **callback_kwargs)
  File "C:\Users\crist\Documents\MYV\mvbotdjango\InstabotMV\views.py", line 278, in tags
    return HttpResponse(json.dumps(tags),content_type='application/json')
  File "C:\Users\crist\AppData\Local\Programs\Python\Python36\lib\json\__init__.py", line 231, in dumps
    return _default_encoder.encode(obj)
  File "C:\Users\crist\AppData\Local\Programs\Python\Python36\lib\json\encoder.py", line 199, in encode
    chunks = self.iterencode(o, _one_shot=True)
  File "C:\Users\crist\AppData\Local\Programs\Python\Python36\lib\json\encoder.py", line 257, in iterencode
    return _iterencode(o, 0)
  File "C:\Users\crist\AppData\Local\Programs\Python\Python36\lib\json\encoder.py", line 180, in default
    o.__class__.__name__)
TypeError: Object of type 'QuerySet' is not JSON serializable
ERROR:django.request:Internal Server Error: /instabotmv/tags/1/
Traceback (most recent call last):
  File "C:\Users\crist\AppData\Local\Programs\Python\Python36\lib\site-packages\django\core\handlers\exception.py", line 34, in inner
    response = get_response(request)
  File "C:\Users\crist\AppData\Local\Programs\Python\Python36\lib\site-packages\django\core\handlers\base.py", line 126, in _get_response
    response = self.process_exception_by_middleware(e, request)
  File "C:\Users\crist\AppData\Local\Programs\Python\Python36\lib\site-packages\django\core\handlers\base.py", line 124, in _get_response
    response = wrapped_callback(request, *callback_args, **callback_kwargs)
  File "C:\Users\crist\Documents\MYV\mvbotdjango\InstabotMV\views.py", line 278, in tags
    return HttpResponse(json.dumps(tags),content_type='application/json')
  File "C:\Users\crist\AppData\Local\Programs\Python\Python36\lib\json\__init__.py", line 231, in dumps
    return _default_encoder.encode(obj)
  File "C:\Users\crist\AppData\Local\Programs\Python\Python36\lib\json\encoder.py", line 199, in encode
    chunks = self.iterencode(o, _one_shot=True)
  File "C:\Users\crist\AppData\Local\Programs\Python\Python36\lib\json\encoder.py", line 257, in iterencode
    return _iterencode(o, 0)
  File "C:\Users\crist\AppData\Local\Programs\Python\Python36\lib\json\encoder.py", line 180, in default
    o.__class__.__name__)
TypeError: Object of type 'QuerySet' is not JSON serializable
ERROR:django.request:Internal Server Error: /instabotmv/hashtag_ajax/
Traceback (most recent call last):
  File "C:\Users\crist\AppData\Local\Programs\Python\Python36\lib\site-packages\django\core\handlers\exception.py", line 34, in inner
    response = get_response(request)
  File "C:\Users\crist\AppData\Local\Programs\Python\Python36\lib\site-packages\django\core\handlers\base.py", line 137, in _get_response
    "returned None instead." % (callback.__module__, view_name)
ValueError: The view InstabotMV.views.hashtags didn't return an HttpResponse object. It returned None instead.
ERROR:django.request:Internal Server Error: /instabotmv/hashtag_ajax/
Traceback (most recent call last):
  File "C:\Users\crist\AppData\Local\Programs\Python\Python36\lib\site-packages\django\core\handlers\exception.py", line 34, in inner
    response = get_response(request)
  File "C:\Users\crist\AppData\Local\Programs\Python\Python36\lib\site-packages\django\core\handlers\base.py", line 137, in _get_response
    "returned None instead." % (callback.__module__, view_name)
ValueError: The view InstabotMV.views.hashtags didn't return an HttpResponse object. It returned None instead.
ERROR:django.request:Internal Server Error: /instabotmv/hashtag_ajax/
Traceback (most recent call last):
  File "C:\Users\crist\AppData\Local\Programs\Python\Python36\lib\site-packages\django\core\handlers\exception.py", line 34, in inner
    response = get_response(request)
  File "C:\Users\crist\AppData\Local\Programs\Python\Python36\lib\site-packages\django\core\handlers\base.py", line 137, in _get_response
    "returned None instead." % (callback.__module__, view_name)
ValueError: The view InstabotMV.views.hashtags didn't return an HttpResponse object. It returned None instead.
ERROR:django.request:Internal Server Error: /instabotmv/hashtag_ajax/
Traceback (most recent call last):
  File "C:\Users\crist\AppData\Local\Programs\Python\Python36\lib\site-packages\django\core\handlers\exception.py", line 34, in inner
    response = get_response(request)
  File "C:\Users\crist\AppData\Local\Programs\Python\Python36\lib\site-packages\django\core\handlers\base.py", line 137, in _get_response
    "returned None instead." % (callback.__module__, view_name)
ValueError: The view InstabotMV.views.hashtags didn't return an HttpResponse object. It returned None instead.
ERROR:django.request:Internal Server Error: /instabotmv/hashtag_ajax/
Traceback (most recent call last):
  File "C:\Users\crist\AppData\Local\Programs\Python\Python36\lib\site-packages\django\core\handlers\exception.py", line 34, in inner
    response = get_response(request)
  File "C:\Users\crist\AppData\Local\Programs\Python\Python36\lib\site-packages\django\core\handlers\base.py", line 137, in _get_response
    "returned None instead." % (callback.__module__, view_name)
ValueError: The view InstabotMV.views.hashtags didn't return an HttpResponse object. It returned None instead.
ERROR:django.request:Internal Server Error: /instabotmv/hashtag_ajax/
Traceback (most recent call last):
  File "C:\Users\crist\AppData\Local\Programs\Python\Python36\lib\site-packages\django\core\handlers\exception.py", line 34, in inner
    response = get_response(request)
  File "C:\Users\crist\AppData\Local\Programs\Python\Python36\lib\site-packages\django\core\handlers\base.py", line 126, in _get_response
    response = self.process_exception_by_middleware(e, request)
  File "C:\Users\crist\AppData\Local\Programs\Python\Python36\lib\site-packages\django\core\handlers\base.py", line 124, in _get_response
    response = wrapped_callback(request, *callback_args, **callback_kwargs)
  File "C:\Users\crist\AppData\Local\Programs\Python\Python36\lib\site-packages\django\views\generic\base.py", line 68, in view
    return self.dispatch(request, *args, **kwargs)
  File "C:\Users\crist\AppData\Local\Programs\Python\Python36\lib\site-packages\django\views\generic\base.py", line 88, in dispatch
    return handler(request, *args, **kwargs)
  File "C:\Users\crist\Documents\MYV\mvbotdjango\InstabotMV\views.py", line 285, in get
    return HttpResponse(data,mimetype='application/json')
  File "C:\Users\crist\AppData\Local\Programs\Python\Python36\lib\site-packages\django\http\response.py", line 289, in __init__
    super().__init__(*args, **kwargs)
TypeError: __init__() got an unexpected keyword argument 'mimetype'
ERROR:django.request:Internal Server Error: /instabotmv/hashtag_ajax/
Traceback (most recent call last):
  File "C:\Users\crist\AppData\Local\Programs\Python\Python36\lib\site-packages\django\core\handlers\exception.py", line 34, in inner
    response = get_response(request)
  File "C:\Users\crist\AppData\Local\Programs\Python\Python36\lib\site-packages\django\core\handlers\base.py", line 126, in _get_response
    response = self.process_exception_by_middleware(e, request)
  File "C:\Users\crist\AppData\Local\Programs\Python\Python36\lib\site-packages\django\core\handlers\base.py", line 124, in _get_response
    response = wrapped_callback(request, *callback_args, **callback_kwargs)
  File "C:\Users\crist\AppData\Local\Programs\Python\Python36\lib\site-packages\django\views\generic\base.py", line 68, in view
    return self.dispatch(request, *args, **kwargs)
  File "C:\Users\crist\AppData\Local\Programs\Python\Python36\lib\site-packages\django\views\generic\base.py", line 88, in dispatch
    return handler(request, *args, **kwargs)
  File "C:\Users\crist\Documents\MYV\mvbotdjango\InstabotMV\views.py", line 285, in get
    return HttpResponse(data,mimetype='application/json')
  File "C:\Users\crist\AppData\Local\Programs\Python\Python36\lib\site-packages\django\http\response.py", line 289, in __init__
    super().__init__(*args, **kwargs)
TypeError: __init__() got an unexpected keyword argument 'mimetype'
ERROR:django.request:Internal Server Error: /instabotmv/hashtag_ajax/
Traceback (most recent call last):
  File "C:\Users\crist\AppData\Local\Programs\Python\Python36\lib\site-packages\django\core\handlers\exception.py", line 34, in inner
    response = get_response(request)
  File "C:\Users\crist\AppData\Local\Programs\Python\Python36\lib\site-packages\django\core\handlers\base.py", line 126, in _get_response
    response = self.process_exception_by_middleware(e, request)
  File "C:\Users\crist\AppData\Local\Programs\Python\Python36\lib\site-packages\django\core\handlers\base.py", line 124, in _get_response
    response = wrapped_callback(request, *callback_args, **callback_kwargs)
  File "C:\Users\crist\AppData\Local\Programs\Python\Python36\lib\site-packages\django\views\generic\base.py", line 68, in view
    return self.dispatch(request, *args, **kwargs)
  File "C:\Users\crist\AppData\Local\Programs\Python\Python36\lib\site-packages\django\views\generic\base.py", line 88, in dispatch
    return handler(request, *args, **kwargs)
  File "C:\Users\crist\Documents\MYV\mvbotdjango\InstabotMV\views.py", line 285, in get
    return HttpResponse(data,mimetype='application/json')
  File "C:\Users\crist\AppData\Local\Programs\Python\Python36\lib\site-packages\django\http\response.py", line 289, in __init__
    super().__init__(*args, **kwargs)
TypeError: __init__() got an unexpected keyword argument 'mimetype'
ERROR:django.request:Internal Server Error: /instabotmv/hashtag_ajax/
Traceback (most recent call last):
  File "C:\Users\crist\AppData\Local\Programs\Python\Python36\lib\site-packages\django\core\handlers\exception.py", line 34, in inner
    response = get_response(request)
  File "C:\Users\crist\AppData\Local\Programs\Python\Python36\lib\site-packages\django\core\handlers\base.py", line 126, in _get_response
    response = self.process_exception_by_middleware(e, request)
  File "C:\Users\crist\AppData\Local\Programs\Python\Python36\lib\site-packages\django\core\handlers\base.py", line 124, in _get_response
    response = wrapped_callback(request, *callback_args, **callback_kwargs)
  File "C:\Users\crist\AppData\Local\Programs\Python\Python36\lib\site-packages\django\views\generic\base.py", line 68, in view
    return self.dispatch(request, *args, **kwargs)
  File "C:\Users\crist\AppData\Local\Programs\Python\Python36\lib\site-packages\django\views\generic\base.py", line 88, in dispatch
    return handler(request, *args, **kwargs)
  File "C:\Users\crist\Documents\MYV\mvbotdjango\InstabotMV\views.py", line 285, in get
    return HttpResponse(data,mimetype='application/json')
  File "C:\Users\crist\AppData\Local\Programs\Python\Python36\lib\site-packages\django\http\response.py", line 289, in __init__
    super().__init__(*args, **kwargs)
TypeError: __init__() got an unexpected keyword argument 'mimetype'
WARNING:django.request:Not Found: /instabotmv/tags/Seleccionar producto/
ERROR:django.request:Internal Server Error: /instabotmv/hashtag_ajax/
Traceback (most recent call last):
  File "C:\Users\crist\AppData\Local\Programs\Python\Python36\lib\site-packages\django\core\handlers\exception.py", line 34, in inner
    response = get_response(request)
  File "C:\Users\crist\AppData\Local\Programs\Python\Python36\lib\site-packages\django\core\handlers\base.py", line 126, in _get_response
    response = self.process_exception_by_middleware(e, request)
  File "C:\Users\crist\AppData\Local\Programs\Python\Python36\lib\site-packages\django\core\handlers\base.py", line 124, in _get_response
    response = wrapped_callback(request, *callback_args, **callback_kwargs)
  File "C:\Users\crist\AppData\Local\Programs\Python\Python36\lib\site-packages\django\views\generic\base.py", line 68, in view
    return self.dispatch(request, *args, **kwargs)
  File "C:\Users\crist\AppData\Local\Programs\Python\Python36\lib\site-packages\django\views\generic\base.py", line 88, in dispatch
    return handler(request, *args, **kwargs)
  File "C:\Users\crist\Documents\MYV\mvbotdjango\InstabotMV\views.py", line 283, in get
    tags = List_Tag.objects.filter(category=idTag)
  File "C:\Users\crist\AppData\Local\Programs\Python\Python36\lib\site-packages\django\db\models\manager.py", line 82, in manager_method
    return getattr(self.get_queryset(), name)(*args, **kwargs)
  File "C:\Users\crist\AppData\Local\Programs\Python\Python36\lib\site-packages\django\db\models\query.py", line 844, in filter
    return self._filter_or_exclude(False, *args, **kwargs)
  File "C:\Users\crist\AppData\Local\Programs\Python\Python36\lib\site-packages\django\db\models\query.py", line 862, in _filter_or_exclude
    clone.query.add_q(Q(*args, **kwargs))
  File "C:\Users\crist\AppData\Local\Programs\Python\Python36\lib\site-packages\django\db\models\sql\query.py", line 1263, in add_q
    clause, _ = self._add_q(q_object, self.used_aliases)
  File "C:\Users\crist\AppData\Local\Programs\Python\Python36\lib\site-packages\django\db\models\sql\query.py", line 1287, in _add_q
    split_subq=split_subq,
  File "C:\Users\crist\AppData\Local\Programs\Python\Python36\lib\site-packages\django\db\models\sql\query.py", line 1225, in build_filter
    condition = self.build_lookup(lookups, col, value)
  File "C:\Users\crist\AppData\Local\Programs\Python\Python36\lib\site-packages\django\db\models\sql\query.py", line 1096, in build_lookup
    lookup = lookup_class(lhs, rhs)
  File "C:\Users\crist\AppData\Local\Programs\Python\Python36\lib\site-packages\django\db\models\lookups.py", line 20, in __init__
    self.rhs = self.get_prep_lookup()
  File "C:\Users\crist\AppData\Local\Programs\Python\Python36\lib\site-packages\django\db\models\fields\related_lookups.py", line 115, in get_prep_lookup
    self.rhs = target_field.get_prep_value(self.rhs)
  File "C:\Users\crist\AppData\Local\Programs\Python\Python36\lib\site-packages\django\db\models\fields\__init__.py", line 965, in get_prep_value
    return int(value)
ValueError: invalid literal for int() with base 10: 'Seleccionar producto'
WARNING:django.request:Not Found: /index
WARNING:django.request:Not Found: /favicon.ico
ERROR:django.request:Internal Server Error: /instabotmv/login/
Traceback (most recent call last):
  File "C:\Users\crist\AppData\Local\Programs\Python\Python36\lib\site-packages\django\core\handlers\exception.py", line 34, in inner
    response = get_response(request)
  File "C:\Users\crist\AppData\Local\Programs\Python\Python36\lib\site-packages\django\core\handlers\base.py", line 126, in _get_response
    response = self.process_exception_by_middleware(e, request)
  File "C:\Users\crist\AppData\Local\Programs\Python\Python36\lib\site-packages\django\core\handlers\base.py", line 124, in _get_response
    response = wrapped_callback(request, *callback_args, **callback_kwargs)
  File "C:\Users\crist\AppData\Local\Programs\Python\Python36\lib\site-packages\django\views\generic\base.py", line 68, in view
    return self.dispatch(request, *args, **kwargs)
  File "C:\Users\crist\AppData\Local\Programs\Python\Python36\lib\site-packages\django\views\generic\base.py", line 88, in dispatch
    return handler(request, *args, **kwargs)
  File "C:\Users\crist\Documents\MYV\mvbotdjango\InstabotMV\views.py", line 175, in post
    return redirect('instabot:dashboard-client')
  File "C:\Users\crist\AppData\Local\Programs\Python\Python36\lib\site-packages\django\shortcuts.py", line 58, in redirect
    return redirect_class(resolve_url(to, *args, **kwargs))
  File "C:\Users\crist\AppData\Local\Programs\Python\Python36\lib\site-packages\django\shortcuts.py", line 148, in resolve_url
    return reverse(to, args=args, kwargs=kwargs)
  File "C:\Users\crist\AppData\Local\Programs\Python\Python36\lib\site-packages\django\urls\base.py", line 90, in reverse
    return iri_to_uri(resolver._reverse_with_prefix(view, prefix, *args, **kwargs))
  File "C:\Users\crist\AppData\Local\Programs\Python\Python36\lib\site-packages\django\urls\resolvers.py", line 622, in _reverse_with_prefix
    raise NoReverseMatch(msg)
django.urls.exceptions.NoReverseMatch: Reverse for 'dashboard-client' not found. 'dashboard-client' is not a valid view function or pattern name.
WARNING:django.request:Not Found: /instabotmv/tags/Seleccionar producto/
ERROR:django.request:Internal Server Error: /instabotmv/hashtag_ajax/
Traceback (most recent call last):
  File "C:\Users\crist\AppData\Local\Programs\Python\Python36\lib\site-packages\django\core\handlers\exception.py", line 34, in inner
    response = get_response(request)
  File "C:\Users\crist\AppData\Local\Programs\Python\Python36\lib\site-packages\django\core\handlers\base.py", line 126, in _get_response
    response = self.process_exception_by_middleware(e, request)
  File "C:\Users\crist\AppData\Local\Programs\Python\Python36\lib\site-packages\django\core\handlers\base.py", line 124, in _get_response
    response = wrapped_callback(request, *callback_args, **callback_kwargs)
  File "C:\Users\crist\AppData\Local\Programs\Python\Python36\lib\site-packages\django\views\generic\base.py", line 68, in view
    return self.dispatch(request, *args, **kwargs)
  File "C:\Users\crist\AppData\Local\Programs\Python\Python36\lib\site-packages\django\views\generic\base.py", line 88, in dispatch
    return handler(request, *args, **kwargs)
  File "C:\Users\crist\Documents\MYV\mvbotdjango\InstabotMV\views.py", line 283, in get
    tags = List_Tag.objects.filter(category=idTag)
  File "C:\Users\crist\AppData\Local\Programs\Python\Python36\lib\site-packages\django\db\models\manager.py", line 82, in manager_method
    return getattr(self.get_queryset(), name)(*args, **kwargs)
  File "C:\Users\crist\AppData\Local\Programs\Python\Python36\lib\site-packages\django\db\models\query.py", line 844, in filter
    return self._filter_or_exclude(False, *args, **kwargs)
  File "C:\Users\crist\AppData\Local\Programs\Python\Python36\lib\site-packages\django\db\models\query.py", line 862, in _filter_or_exclude
    clone.query.add_q(Q(*args, **kwargs))
  File "C:\Users\crist\AppData\Local\Programs\Python\Python36\lib\site-packages\django\db\models\sql\query.py", line 1263, in add_q
    clause, _ = self._add_q(q_object, self.used_aliases)
  File "C:\Users\crist\AppData\Local\Programs\Python\Python36\lib\site-packages\django\db\models\sql\query.py", line 1287, in _add_q
    split_subq=split_subq,
  File "C:\Users\crist\AppData\Local\Programs\Python\Python36\lib\site-packages\django\db\models\sql\query.py", line 1225, in build_filter
    condition = self.build_lookup(lookups, col, value)
  File "C:\Users\crist\AppData\Local\Programs\Python\Python36\lib\site-packages\django\db\models\sql\query.py", line 1096, in build_lookup
    lookup = lookup_class(lhs, rhs)
  File "C:\Users\crist\AppData\Local\Programs\Python\Python36\lib\site-packages\django\db\models\lookups.py", line 20, in __init__
    self.rhs = self.get_prep_lookup()
  File "C:\Users\crist\AppData\Local\Programs\Python\Python36\lib\site-packages\django\db\models\fields\related_lookups.py", line 115, in get_prep_lookup
    self.rhs = target_field.get_prep_value(self.rhs)
  File "C:\Users\crist\AppData\Local\Programs\Python\Python36\lib\site-packages\django\db\models\fields\__init__.py", line 965, in get_prep_value
    return int(value)
ValueError: invalid literal for int() with base 10: 'Seleccionar producto'
WARNING:django.request:Not Found: /accounts/login/
ERROR:django.request:Internal Server Error: /instabotmv/login/
Traceback (most recent call last):
  File "C:\Users\crist\AppData\Local\Programs\Python\Python36\lib\site-packages\django\core\handlers\exception.py", line 34, in inner
    response = get_response(request)
  File "C:\Users\crist\AppData\Local\Programs\Python\Python36\lib\site-packages\django\core\handlers\base.py", line 126, in _get_response
    response = self.process_exception_by_middleware(e, request)
  File "C:\Users\crist\AppData\Local\Programs\Python\Python36\lib\site-packages\django\core\handlers\base.py", line 124, in _get_response
    response = wrapped_callback(request, *callback_args, **callback_kwargs)
  File "C:\Users\crist\AppData\Local\Programs\Python\Python36\lib\site-packages\django\views\generic\base.py", line 68, in view
    return self.dispatch(request, *args, **kwargs)
  File "C:\Users\crist\AppData\Local\Programs\Python\Python36\lib\site-packages\django\views\generic\base.py", line 88, in dispatch
    return handler(request, *args, **kwargs)
  File "C:\Users\crist\Documents\MYV\mvbotdjango\InstabotMV\views.py", line 171, in post
    if user.is_superuser == 1:
AttributeError: 'NoneType' object has no attribute 'is_superuser'
ERROR:django.request:Internal Server Error: /instabotmv/login/
Traceback (most recent call last):
  File "C:\Users\crist\AppData\Local\Programs\Python\Python36\lib\site-packages\django\core\handlers\exception.py", line 34, in inner
    response = get_response(request)
  File "C:\Users\crist\AppData\Local\Programs\Python\Python36\lib\site-packages\django\core\handlers\base.py", line 126, in _get_response
    response = self.process_exception_by_middleware(e, request)
  File "C:\Users\crist\AppData\Local\Programs\Python\Python36\lib\site-packages\django\core\handlers\base.py", line 124, in _get_response
    response = wrapped_callback(request, *callback_args, **callback_kwargs)
  File "C:\Users\crist\AppData\Local\Programs\Python\Python36\lib\site-packages\django\views\generic\base.py", line 68, in view
    return self.dispatch(request, *args, **kwargs)
  File "C:\Users\crist\AppData\Local\Programs\Python\Python36\lib\site-packages\django\views\generic\base.py", line 88, in dispatch
    return handler(request, *args, **kwargs)
  File "C:\Users\crist\Documents\MYV\mvbotdjango\InstabotMV\views.py", line 176, in post
    return redirect('instabot:dashboard-client')
  File "C:\Users\crist\AppData\Local\Programs\Python\Python36\lib\site-packages\django\shortcuts.py", line 58, in redirect
    return redirect_class(resolve_url(to, *args, **kwargs))
  File "C:\Users\crist\AppData\Local\Programs\Python\Python36\lib\site-packages\django\shortcuts.py", line 148, in resolve_url
    return reverse(to, args=args, kwargs=kwargs)
  File "C:\Users\crist\AppData\Local\Programs\Python\Python36\lib\site-packages\django\urls\base.py", line 90, in reverse
    return iri_to_uri(resolver._reverse_with_prefix(view, prefix, *args, **kwargs))
  File "C:\Users\crist\AppData\Local\Programs\Python\Python36\lib\site-packages\django\urls\resolvers.py", line 622, in _reverse_with_prefix
    raise NoReverseMatch(msg)
django.urls.exceptions.NoReverseMatch: Reverse for 'dashboard-client' not found. 'dashboard-client' is not a valid view function or pattern name.
WARNING:django.security.csrf:Forbidden (CSRF token missing or incorrect.): /instabotmv/login/
WARNING:django.security.csrf:Forbidden (CSRF token missing or incorrect.): /instabotmv/login/
ERROR:django.request:Internal Server Error: /instabotmv/login/
Traceback (most recent call last):
  File "C:\Users\crist\AppData\Local\Programs\Python\Python36\lib\site-packages\django\core\handlers\exception.py", line 34, in inner
    response = get_response(request)
  File "C:\Users\crist\AppData\Local\Programs\Python\Python36\lib\site-packages\django\core\handlers\base.py", line 126, in _get_response
    response = self.process_exception_by_middleware(e, request)
  File "C:\Users\crist\AppData\Local\Programs\Python\Python36\lib\site-packages\django\core\handlers\base.py", line 124, in _get_response
    response = wrapped_callback(request, *callback_args, **callback_kwargs)
  File "C:\Users\crist\AppData\Local\Programs\Python\Python36\lib\site-packages\django\views\generic\base.py", line 68, in view
    return self.dispatch(request, *args, **kwargs)
  File "C:\Users\crist\AppData\Local\Programs\Python\Python36\lib\site-packages\django\views\generic\base.py", line 88, in dispatch
    return handler(request, *args, **kwargs)
  File "C:\Users\crist\Documents\MYV\mvbotdjango\InstabotMV\views.py", line 176, in post
    return redirect('instabot:dashboard-client')
  File "C:\Users\crist\AppData\Local\Programs\Python\Python36\lib\site-packages\django\shortcuts.py", line 58, in redirect
    return redirect_class(resolve_url(to, *args, **kwargs))
  File "C:\Users\crist\AppData\Local\Programs\Python\Python36\lib\site-packages\django\shortcuts.py", line 148, in resolve_url
    return reverse(to, args=args, kwargs=kwargs)
  File "C:\Users\crist\AppData\Local\Programs\Python\Python36\lib\site-packages\django\urls\base.py", line 90, in reverse
    return iri_to_uri(resolver._reverse_with_prefix(view, prefix, *args, **kwargs))
  File "C:\Users\crist\AppData\Local\Programs\Python\Python36\lib\site-packages\django\urls\resolvers.py", line 622, in _reverse_with_prefix
    raise NoReverseMatch(msg)
django.urls.exceptions.NoReverseMatch: Reverse for 'dashboard-client' not found. 'dashboard-client' is not a valid view function or pattern name.
WARNING:django.security.csrf:Forbidden (CSRF token missing or incorrect.): /instabotmv/login/
WARNING:django.security.csrf:Forbidden (CSRF token missing or incorrect.): /instabotmv/login/
ERROR:django.request:Internal Server Error: /instabotmv/dashboard/task/new/follow-like/
Traceback (most recent call last):
  File "C:\Users\crist\AppData\Local\Programs\Python\Python36\lib\site-packages\django\core\handlers\exception.py", line 34, in inner
    response = get_response(request)
  File "C:\Users\crist\AppData\Local\Programs\Python\Python36\lib\site-packages\django\core\handlers\base.py", line 126, in _get_response
    response = self.process_exception_by_middleware(e, request)
  File "C:\Users\crist\AppData\Local\Programs\Python\Python36\lib\site-packages\django\core\handlers\base.py", line 124, in _get_response
    response = wrapped_callback(request, *callback_args, **callback_kwargs)
  File "C:\Users\crist\AppData\Local\Programs\Python\Python36\lib\site-packages\django\views\generic\base.py", line 68, in view
    return self.dispatch(request, *args, **kwargs)
  File "C:\Users\crist\AppData\Local\Programs\Python\Python36\lib\site-packages\django\contrib\auth\mixins.py", line 52, in dispatch
    return super().dispatch(request, *args, **kwargs)
  File "C:\Users\crist\AppData\Local\Programs\Python\Python36\lib\site-packages\django\views\generic\base.py", line 88, in dispatch
    return handler(request, *args, **kwargs)
  File "C:\Users\crist\Documents\MYV\mvbotdjango\InstabotMV\views.py", line 309, in get
    return render(request, 'tasks/followAndLike.html', {'Hasgtags': Hasgtags,'user':user})
NameError: name 'user' is not defined
ERROR:django.request:Internal Server Error: /instabotmv/dashboard/task/new/follow-like/
Traceback (most recent call last):
  File "C:\Users\crist\AppData\Local\Programs\Python\Python36\lib\site-packages\django\core\handlers\exception.py", line 34, in inner
    response = get_response(request)
  File "C:\Users\crist\AppData\Local\Programs\Python\Python36\lib\site-packages\django\core\handlers\base.py", line 126, in _get_response
    response = self.process_exception_by_middleware(e, request)
  File "C:\Users\crist\AppData\Local\Programs\Python\Python36\lib\site-packages\django\core\handlers\base.py", line 124, in _get_response
    response = wrapped_callback(request, *callback_args, **callback_kwargs)
  File "C:\Users\crist\AppData\Local\Programs\Python\Python36\lib\site-packages\django\views\generic\base.py", line 68, in view
    return self.dispatch(request, *args, **kwargs)
  File "C:\Users\crist\AppData\Local\Programs\Python\Python36\lib\site-packages\django\contrib\auth\mixins.py", line 52, in dispatch
    return super().dispatch(request, *args, **kwargs)
  File "C:\Users\crist\AppData\Local\Programs\Python\Python36\lib\site-packages\django\views\generic\base.py", line 88, in dispatch
    return handler(request, *args, **kwargs)
  File "C:\Users\crist\Documents\MYV\mvbotdjango\InstabotMV\views.py", line 309, in get
    return render(request, 'tasks/followAndLike.html', {'Hasgtags': Hasgtags,'user':user})
NameError: name 'user' is not defined
WARNING:django.request:Not Found: /instabotmv/dashboard/task/new/follow-like/obtener()
WARNING:django.request:Not Found: /instabotmv/dashboard/task/new/follow-like/obtener()
WARNING:django.request:Not Found: /instabotmv/dashboard/task/new/follow-like/obtener()
WARNING:django.request:Method Not Allowed (POST): /instabotmv/dashboard/task/new/follow-like/
WARNING:django.request:Method Not Allowed: /instabotmv/dashboard/task/new/follow-like/
WARNING:django.request:Method Not Allowed (POST): /instabotmv/dashboard/task/new/follow-like/
WARNING:django.request:Method Not Allowed: /instabotmv/dashboard/task/new/follow-like/
WARNING:django.request:Method Not Allowed (POST): /instabotmv/dashboard/task/new/follow-like/
WARNING:django.request:Method Not Allowed: /instabotmv/dashboard/task/new/follow-like/
WARNING:django.request:Method Not Allowed (POST): /instabotmv/dashboard/task/new/follow-like/
WARNING:django.request:Method Not Allowed: /instabotmv/dashboard/task/new/follow-like/
WARNING:django.request:Method Not Allowed (POST): /instabotmv/dashboard/task/new/follow-like/
WARNING:django.request:Method Not Allowed: /instabotmv/dashboard/task/new/follow-like/
WARNING:django.request:Method Not Allowed (POST): /instabotmv/dashboard/task/new/follow-like/
WARNING:django.request:Method Not Allowed: /instabotmv/dashboard/task/new/follow-like/
WARNING:django.request:Method Not Allowed (GET): /instabotmv/dashboard/task/new/follow-like/
WARNING:django.request:Method Not Allowed: /instabotmv/dashboard/task/new/follow-like/
WARNING:django.request:Method Not Allowed (GET): /instabotmv/dashboard/task/new/follow-like/
WARNING:django.request:Method Not Allowed: /instabotmv/dashboard/task/new/follow-like/
WARNING:django.request:Method Not Allowed (GET): /instabotmv/dashboard/task/new/follow-like/
WARNING:django.request:Method Not Allowed: /instabotmv/dashboard/task/new/follow-like/
WARNING:django.request:Method Not Allowed (GET): /instabotmv/dashboard/task/new/follow-like/
WARNING:django.request:Method Not Allowed: /instabotmv/dashboard/task/new/follow-like/
WARNING:django.request:Method Not Allowed (GET): /instabotmv/dashboard/task/new/follow-like/
WARNING:django.request:Method Not Allowed: /instabotmv/dashboard/task/new/follow-like/
WARNING:django.request:Method Not Allowed (GET): /instabotmv/dashboard/task/new/follow-like/
WARNING:django.request:Method Not Allowed: /instabotmv/dashboard/task/new/follow-like/
WARNING:django.request:Method Not Allowed (GET): /instabotmv/dashboard/task/new/follow-like/
WARNING:django.request:Method Not Allowed: /instabotmv/dashboard/task/new/follow-like/
WARNING:django.request:Method Not Allowed (POST): /instabotmv/dashboard/task/new/follow-like/
WARNING:django.request:Method Not Allowed: /instabotmv/dashboard/task/new/follow-like/
ERROR:django.request:Internal Server Error: /instabotmv/stop-bot/
Traceback (most recent call last):
  File "C:\Users\crist\AppData\Local\Programs\Python\Python36\lib\site-packages\django\core\handlers\exception.py", line 34, in inner
    response = get_response(request)
  File "C:\Users\crist\AppData\Local\Programs\Python\Python36\lib\site-packages\django\core\handlers\base.py", line 126, in _get_response
    response = self.process_exception_by_middleware(e, request)
  File "C:\Users\crist\AppData\Local\Programs\Python\Python36\lib\site-packages\django\core\handlers\base.py", line 124, in _get_response
    response = wrapped_callback(request, *callback_args, **callback_kwargs)
  File "C:\Users\crist\AppData\Local\Programs\Python\Python36\lib\site-packages\django\views\generic\base.py", line 68, in view
    return self.dispatch(request, *args, **kwargs)
  File "C:\Users\crist\AppData\Local\Programs\Python\Python36\lib\site-packages\django\contrib\auth\mixins.py", line 52, in dispatch
    return super().dispatch(request, *args, **kwargs)
  File "C:\Users\crist\AppData\Local\Programs\Python\Python36\lib\site-packages\django\views\generic\base.py", line 88, in dispatch
    return handler(request, *args, **kwargs)
TypeError: post() takes 1 positional argument but 2 were given
WARNING:django.request:Not Found: /favicon.ico
WARNING:django.request:Not Found: /favicon.ico
WARNING:django.request:Not Found: /instabotmv/tags/Seleccionar producto/
ERROR:django.request:Internal Server Error: /instabotmv/hashtag_ajax/
Traceback (most recent call last):
  File "C:\Users\crist\AppData\Local\Programs\Python\Python36\lib\site-packages\django\core\handlers\exception.py", line 34, in inner
    response = get_response(request)
  File "C:\Users\crist\AppData\Local\Programs\Python\Python36\lib\site-packages\django\core\handlers\base.py", line 126, in _get_response
    response = self.process_exception_by_middleware(e, request)
  File "C:\Users\crist\AppData\Local\Programs\Python\Python36\lib\site-packages\django\core\handlers\base.py", line 124, in _get_response
    response = wrapped_callback(request, *callback_args, **callback_kwargs)
  File "C:\Users\crist\AppData\Local\Programs\Python\Python36\lib\site-packages\django\views\generic\base.py", line 68, in view
    return self.dispatch(request, *args, **kwargs)
  File "C:\Users\crist\AppData\Local\Programs\Python\Python36\lib\site-packages\django\views\generic\base.py", line 88, in dispatch
    return handler(request, *args, **kwargs)
  File "C:\Users\crist\Documents\MYV\mvbotdjango\InstabotMV\views.py", line 295, in get
    tags = List_Tag.objects.filter(category=idTag)
  File "C:\Users\crist\AppData\Local\Programs\Python\Python36\lib\site-packages\django\db\models\manager.py", line 82, in manager_method
    return getattr(self.get_queryset(), name)(*args, **kwargs)
  File "C:\Users\crist\AppData\Local\Programs\Python\Python36\lib\site-packages\django\db\models\query.py", line 844, in filter
    return self._filter_or_exclude(False, *args, **kwargs)
  File "C:\Users\crist\AppData\Local\Programs\Python\Python36\lib\site-packages\django\db\models\query.py", line 862, in _filter_or_exclude
    clone.query.add_q(Q(*args, **kwargs))
  File "C:\Users\crist\AppData\Local\Programs\Python\Python36\lib\site-packages\django\db\models\sql\query.py", line 1263, in add_q
    clause, _ = self._add_q(q_object, self.used_aliases)
  File "C:\Users\crist\AppData\Local\Programs\Python\Python36\lib\site-packages\django\db\models\sql\query.py", line 1287, in _add_q
    split_subq=split_subq,
  File "C:\Users\crist\AppData\Local\Programs\Python\Python36\lib\site-packages\django\db\models\sql\query.py", line 1225, in build_filter
    condition = self.build_lookup(lookups, col, value)
  File "C:\Users\crist\AppData\Local\Programs\Python\Python36\lib\site-packages\django\db\models\sql\query.py", line 1096, in build_lookup
    lookup = lookup_class(lhs, rhs)
  File "C:\Users\crist\AppData\Local\Programs\Python\Python36\lib\site-packages\django\db\models\lookups.py", line 20, in __init__
    self.rhs = self.get_prep_lookup()
  File "C:\Users\crist\AppData\Local\Programs\Python\Python36\lib\site-packages\django\db\models\fields\related_lookups.py", line 115, in get_prep_lookup
    self.rhs = target_field.get_prep_value(self.rhs)
  File "C:\Users\crist\AppData\Local\Programs\Python\Python36\lib\site-packages\django\db\models\fields\__init__.py", line 965, in get_prep_value
    return int(value)
ValueError: invalid literal for int() with base 10: 'Seleccionar producto'
WARNING:django.request:Not Found: /index
WARNING:django.request:Not Found: /favicon.ico
WARNING:django.request:Not Found: /favicon.ico
WARNING:django.request:Not Found: /instabotmv/tags/Seleccionar producto/
ERROR:django.request:Internal Server Error: /instabotmv/hashtag_ajax/
Traceback (most recent call last):
  File "C:\Users\crist\AppData\Local\Programs\Python\Python36\lib\site-packages\django\core\handlers\exception.py", line 34, in inner
    response = get_response(request)
  File "C:\Users\crist\AppData\Local\Programs\Python\Python36\lib\site-packages\django\core\handlers\base.py", line 126, in _get_response
    response = self.process_exception_by_middleware(e, request)
  File "C:\Users\crist\AppData\Local\Programs\Python\Python36\lib\site-packages\django\core\handlers\base.py", line 124, in _get_response
    response = wrapped_callback(request, *callback_args, **callback_kwargs)
  File "C:\Users\crist\AppData\Local\Programs\Python\Python36\lib\site-packages\django\views\generic\base.py", line 68, in view
    return self.dispatch(request, *args, **kwargs)
  File "C:\Users\crist\AppData\Local\Programs\Python\Python36\lib\site-packages\django\views\generic\base.py", line 88, in dispatch
    return handler(request, *args, **kwargs)
  File "C:\Users\crist\Documents\MYV\mvbotdjango\InstabotMV\views.py", line 295, in get
    tags = List_Tag.objects.filter(category=idTag)
  File "C:\Users\crist\AppData\Local\Programs\Python\Python36\lib\site-packages\django\db\models\manager.py", line 82, in manager_method
    return getattr(self.get_queryset(), name)(*args, **kwargs)
  File "C:\Users\crist\AppData\Local\Programs\Python\Python36\lib\site-packages\django\db\models\query.py", line 844, in filter
    return self._filter_or_exclude(False, *args, **kwargs)
  File "C:\Users\crist\AppData\Local\Programs\Python\Python36\lib\site-packages\django\db\models\query.py", line 862, in _filter_or_exclude
    clone.query.add_q(Q(*args, **kwargs))
  File "C:\Users\crist\AppData\Local\Programs\Python\Python36\lib\site-packages\django\db\models\sql\query.py", line 1263, in add_q
    clause, _ = self._add_q(q_object, self.used_aliases)
  File "C:\Users\crist\AppData\Local\Programs\Python\Python36\lib\site-packages\django\db\models\sql\query.py", line 1287, in _add_q
    split_subq=split_subq,
  File "C:\Users\crist\AppData\Local\Programs\Python\Python36\lib\site-packages\django\db\models\sql\query.py", line 1225, in build_filter
    condition = self.build_lookup(lookups, col, value)
  File "C:\Users\crist\AppData\Local\Programs\Python\Python36\lib\site-packages\django\db\models\sql\query.py", line 1096, in build_lookup
    lookup = lookup_class(lhs, rhs)
  File "C:\Users\crist\AppData\Local\Programs\Python\Python36\lib\site-packages\django\db\models\lookups.py", line 20, in __init__
    self.rhs = self.get_prep_lookup()
  File "C:\Users\crist\AppData\Local\Programs\Python\Python36\lib\site-packages\django\db\models\fields\related_lookups.py", line 115, in get_prep_lookup
    self.rhs = target_field.get_prep_value(self.rhs)
  File "C:\Users\crist\AppData\Local\Programs\Python\Python36\lib\site-packages\django\db\models\fields\__init__.py", line 965, in get_prep_value
    return int(value)
ValueError: invalid literal for int() with base 10: 'Seleccionar producto'
